Attaching to service_main, service_author, service_presentation
[36mservice_author          |[0m 2023-05-29T16:01:17.010346391Z INFO:     Will watch for changes in these directories: ['/']
[36mservice_author          |[0m 2023-05-29T16:01:17.012808204Z INFO:     Uvicorn running on http://0.0.0.0:8081 (Press CTRL+C to quit)
[36mservice_author          |[0m 2023-05-29T16:01:17.013432657Z INFO:     Started reloader process [1] using WatchFiles
[36mservice_author          |[0m 2023-05-29T16:01:18.509819855Z INFO:     Started server process [10]
[36mservice_author          |[0m 2023-05-29T16:01:18.509848107Z INFO:     Waiting for application startup.
[36mservice_author          |[0m 2023-05-29T16:01:18.513635638Z INFO:     Application startup complete.
[36mservice_author          |[0m 2023-05-29T16:01:25.756926154Z <class 'list'>
[36mservice_author          |[0m 2023-05-29T16:01:25.756961921Z INFO:     172.18.0.4:33492 - "GET /authors/1 HTTP/1.1" 200 OK
[36mservice_author          |[0m 2023-05-29T16:01:27.108713940Z INFO:     172.18.0.4:33500 - "GET /authors/1 HTTP/1.1" 200 OK
[36mservice_author          |[0m 2023-05-29T16:01:28.353477097Z INFO:     172.18.0.4:33508 - "GET /authors/1 HTTP/1.1" 200 OK
[36mservice_author          |[0m 2023-05-29T16:02:16.389929528Z INFO:     Will watch for changes in these directories: ['/']
[36mservice_author          |[0m 2023-05-29T16:02:16.390822559Z INFO:     Uvicorn running on http://0.0.0.0:8081 (Press CTRL+C to quit)
[36mservice_author          |[0m 2023-05-29T16:02:16.392205777Z INFO:     Started reloader process [1] using WatchFiles
[36mservice_author          |[0m 2023-05-29T16:02:17.907048895Z INFO:     Started server process [9]
[36mservice_author          |[0m 2023-05-29T16:02:17.907495344Z INFO:     Waiting for application startup.
[36mservice_author          |[0m 2023-05-29T16:02:17.908481926Z INFO:     Application startup complete.
[36mservice_author          |[0m 2023-05-29T16:02:20.040408562Z <class 'list'>
[36mservice_author          |[0m 2023-05-29T16:02:20.040448918Z INFO:     172.18.0.4:33594 - "GET /authors/1 HTTP/1.1" 200 OK
[36mservice_author          |[0m 2023-05-29T16:02:26.263778672Z INFO:     172.18.0.4:33602 - "GET /authors/1 HTTP/1.1" 200 OK
[36mservice_author          |[0m 2023-05-29T16:02:28.061102057Z INFO:     172.18.0.4:33610 - "GET /authors/1 HTTP/1.1" 200 OK
[33mservice_main            |[0m 2023-05-29T16:01:18.420158318Z INFO:     Will watch for changes in these directories: ['/']
[33mservice_main            |[0m 2023-05-29T16:01:18.425624666Z INFO:     Uvicorn running on http://0.0.0.0:8083 (Press CTRL+C to quit)
[33mservice_main            |[0m 2023-05-29T16:01:18.426387932Z INFO:     Started reloader process [1] using WatchFiles
[33mservice_main            |[0m 2023-05-29T16:01:19.910566438Z INFO:     Started server process [8]
[33mservice_main            |[0m 2023-05-29T16:01:19.911157501Z INFO:     Waiting for application startup.
[33mservice_main            |[0m 2023-05-29T16:01:19.919895722Z INFO:     Application startup complete.
[33mservice_main            |[0m 2023-05-29T16:01:20.912402755Z WARNING:root:Circuit "test-08" is "Status.CLOSED", failures: 0
[33mservice_main            |[0m 2023-05-29T16:01:20.938563979Z WARNING:root:
[33mservice_main            |[0m 2023-05-29T16:01:21.942105681Z WARNING:root:Circuit "test-08" is "Status.CLOSED", failures: 0
[33mservice_main            |[0m 2023-05-29T16:01:21.958057347Z WARNING:root:
[33mservice_main            |[0m 2023-05-29T16:01:22.966298486Z WARNING:root:Circuit "test-08" is "Status.CLOSED", failures: 0
[33mservice_main            |[0m 2023-05-29T16:01:22.986228648Z WARNING:root:
[33mservice_main            |[0m 2023-05-29T16:01:23.990336260Z WARNING:root:Circuit "test-08" is "Status.CLOSED", failures: 0
[33mservice_main            |[0m 2023-05-29T16:01:24.018698241Z WARNING:root:
[33mservice_main            |[0m 2023-05-29T16:01:25.022598952Z WARNING:root:Circuit "test-08" is "Status.CLOSED", failures: 0
[33mservice_main            |[0m 2023-05-29T16:01:25.075583433Z WARNING:root:
[33mservice_main            |[0m 2023-05-29T16:01:25.758916306Z Moore
[33mservice_main            |[0m 2023-05-29T16:01:25.758942657Z INFO:     172.18.0.1:59958 - "GET /presentationsAndAuthor/First%20Presentation HTTP/1.1" 200 OK
[33mservice_main            |[0m 2023-05-29T16:01:26.081820274Z WARNING:root:Circuit "test-08" is "Status.CLOSED", failures: 0
[33mservice_main            |[0m 2023-05-29T16:01:26.107714183Z WARNING:root:
[33mservice_main            |[0m 2023-05-29T16:01:27.111377851Z WARNING:root:Circuit "test-08" is "Status.CLOSED", failures: 0
[33mservice_main            |[0m 2023-05-29T16:01:27.122684707Z Moore
[33mservice_main            |[0m 2023-05-29T16:01:27.122711697Z INFO:     172.18.0.1:59966 - "GET /presentationsAndAuthor/First%20Presentation HTTP/1.1" 200 OK
[33mservice_main            |[0m 2023-05-29T16:01:27.133564029Z WARNING:root:
[33mservice_main            |[0m 2023-05-29T16:01:28.137096652Z WARNING:root:Circuit "test-08" is "Status.CLOSED", failures: 0
[33mservice_main            |[0m 2023-05-29T16:01:28.158941856Z WARNING:root:
[33mservice_main            |[0m 2023-05-29T16:01:28.355297514Z Moore
[33mservice_main            |[0m 2023-05-29T16:01:28.355324134Z INFO:     172.18.0.1:59974 - "GET /presentationsAndAuthor/First%20Presentation HTTP/1.1" 200 OK
[33mservice_main            |[0m 2023-05-29T16:01:29.167840877Z WARNING:root:Circuit "test-08" is "Status.CLOSED", failures: 0
[33mservice_main            |[0m 2023-05-29T16:01:29.190483669Z WARNING:root:
[33mservice_main            |[0m 2023-05-29T16:01:30.186669976Z WARNING:root:Circuit "test-08" is "Status.CLOSED", failures: 0
[33mservice_main            |[0m 2023-05-29T16:01:30.210996729Z WARNING:root:
[33mservice_main            |[0m 2023-05-29T16:01:31.218328852Z WARNING:root:Circuit "test-08" is "Status.CLOSED", failures: 0
[33mservice_main            |[0m 2023-05-29T16:01:31.270455863Z WARNING:root:
[33mservice_main            |[0m 2023-05-29T16:01:32.274038304Z WARNING:root:Circuit "test-08" is "Status.CLOSED", failures: 0
[33mservice_main            |[0m 2023-05-29T16:01:32.343651847Z WARNING:root:
[33mservice_main            |[0m 2023-05-29T16:01:33.354929918Z WARNING:root:Circuit "test-08" is "Status.CLOSED", failures: 0
[33mservice_main            |[0m 2023-05-29T16:01:33.391996762Z WARNING:root:
[33mservice_main            |[0m 2023-05-29T16:01:34.395161505Z WARNING:root:Circuit "test-08" is "Status.CLOSED", failures: 0
[33mservice_main            |[0m 2023-05-29T16:01:34.411171000Z WARNING:root:
[33mservice_main            |[0m 2023-05-29T16:01:35.428964329Z WARNING:root:Circuit "test-08" is "Status.CLOSED", failures: 0
[33mservice_main            |[0m 2023-05-29T16:01:35.449568097Z WARNING:root:
[33mservice_main            |[0m 2023-05-29T16:01:36.459331333Z WARNING:root:Circuit "test-08" is "Status.CLOSED", failures: 0
[33mservice_main            |[0m 2023-05-29T16:01:36.476971175Z WARNING:root:
[33mservice_main            |[0m 2023-05-29T16:01:37.480076622Z WARNING:root:Circuit "test-08" is "Status.CLOSED", failures: 0
[33mservice_main            |[0m 2023-05-29T16:01:37.512371681Z WARNING:root:
[33mservice_main            |[0m 2023-05-29T16:01:38.515151930Z WARNING:root:Circuit "test-08" is "Status.CLOSED", failures: 0
[33mservice_main            |[0m 2023-05-29T16:01:38.533530612Z WARNING:root:
[33mservice_main            |[0m 2023-05-29T16:01:39.536960223Z WARNING:root:Circuit "test-08" is "Status.CLOSED", failures: 0
[33mservice_main            |[0m 2023-05-29T16:01:39.554344612Z WARNING:root:
[33mservice_main            |[0m 2023-05-29T16:01:40.557020530Z WARNING:root:Circuit "test-08" is "Status.CLOSED", failures: 0
[33mservice_main            |[0m 2023-05-29T16:01:40.570383165Z WARNING:root:
[33mservice_main            |[0m 2023-05-29T16:01:41.573093594Z WARNING:root:Circuit "test-08" is "Status.CLOSED", failures: 0
[33mservice_main            |[0m 2023-05-29T16:01:41.596451416Z WARNING:root:
[33mservice_main            |[0m 2023-05-29T16:01:42.604085509Z WARNING:root:Circuit "test-08" is "Status.CLOSED", failures: 0
[33mservice_main            |[0m 2023-05-29T16:01:42.630879007Z WARNING:root:
[33mservice_main            |[0m 2023-05-29T16:01:43.635042839Z WARNING:root:Circuit "test-08" is "Status.CLOSED", failures: 0
[33mservice_main            |[0m 2023-05-29T16:01:43.653079126Z WARNING:root:
[33mservice_main            |[0m 2023-05-29T16:01:44.656140784Z WARNING:root:Circuit "test-08" is "Status.CLOSED", failures: 0
[33mservice_main            |[0m 2023-05-29T16:01:44.712434117Z WARNING:root:
[33mservice_main            |[0m 2023-05-29T16:01:45.713151336Z WARNING:root:Circuit "test-08" is "Status.CLOSED", failures: 0
[33mservice_main            |[0m 2023-05-29T16:01:45.760273890Z WARNING:root:
[33mservice_main            |[0m 2023-05-29T16:01:46.763028520Z WARNING:root:Circuit "test-08" is "Status.CLOSED", failures: 0
[33mservice_main            |[0m 2023-05-29T16:01:46.782110188Z WARNING:root:
[33mservice_main            |[0m 2023-05-29T16:01:47.666344220Z --- Logging error ---
[33mservice_main            |[0m 2023-05-29T16:01:47.676638972Z Traceback (most recent call last):
[33mservice_main            |[0m 2023-05-29T16:01:47.685272782Z   File "/usr/local/lib/python3.10/dist-packages/urllib3/connection.py", line 174, in _new_conn
[33mservice_main            |[0m 2023-05-29T16:01:47.685445872Z     conn = connection.create_connection(
[33mservice_main            |[0m 2023-05-29T16:01:47.685459485Z   File "/usr/local/lib/python3.10/dist-packages/urllib3/util/connection.py", line 72, in create_connection
[33mservice_main            |[0m 2023-05-29T16:01:47.685466040Z     for res in socket.getaddrinfo(host, port, family, socket.SOCK_STREAM):
[33mservice_main            |[0m 2023-05-29T16:01:47.685472273Z   File "/usr/lib/python3.10/socket.py", line 955, in getaddrinfo
[33mservice_main            |[0m 2023-05-29T16:01:47.685477894Z     for res in _socket.getaddrinfo(host, port, family, type, proto, flags):
[33mservice_main            |[0m 2023-05-29T16:01:47.685659042Z socket.gaierror: [Errno -2] Name or service not known
[33mservice_main            |[0m 2023-05-29T16:01:47.685696545Z 
[33mservice_main            |[0m 2023-05-29T16:01:47.685757046Z During handling of the above exception, another exception occurred:
[33mservice_main            |[0m 2023-05-29T16:01:47.685780328Z 
[33mservice_main            |[0m 2023-05-29T16:01:47.685787352Z Traceback (most recent call last):
[33mservice_main            |[0m 2023-05-29T16:01:47.685792579Z   File "/usr/local/lib/python3.10/dist-packages/urllib3/connectionpool.py", line 703, in urlopen
[33mservice_main            |[0m 2023-05-29T16:01:47.685797537Z     httplib_response = self._make_request(
[33mservice_main            |[0m 2023-05-29T16:01:47.685802313Z   File "/usr/local/lib/python3.10/dist-packages/urllib3/connectionpool.py", line 398, in _make_request
[33mservice_main            |[0m 2023-05-29T16:01:47.685807534Z     conn.request(method, url, **httplib_request_kw)
[33mservice_main            |[0m 2023-05-29T16:01:47.685812226Z   File "/usr/local/lib/python3.10/dist-packages/urllib3/connection.py", line 239, in request
[33mservice_main            |[0m 2023-05-29T16:01:47.685817605Z     super(HTTPConnection, self).request(method, url, body=body, headers=headers)
[33mservice_main            |[0m 2023-05-29T16:01:47.687494082Z   File "/usr/lib/python3.10/http/client.py", line 1282, in request
[33mservice_main            |[0m 2023-05-29T16:01:47.687529781Z     self._send_request(method, url, body, headers, encode_chunked)
[33mservice_main            |[0m 2023-05-29T16:01:47.687671705Z   File "/usr/lib/python3.10/http/client.py", line 1328, in _send_request
[33mservice_main            |[0m 2023-05-29T16:01:47.687688228Z     self.endheaders(body, encode_chunked=encode_chunked)
[33mservice_main            |[0m 2023-05-29T16:01:47.687695763Z   File "/usr/lib/python3.10/http/client.py", line 1277, in endheaders
[33mservice_main            |[0m 2023-05-29T16:01:47.687701931Z     self._send_output(message_body, encode_chunked=encode_chunked)
[33mservice_main            |[0m 2023-05-29T16:01:47.689866870Z   File "/usr/lib/python3.10/http/client.py", line 1037, in _send_output
[33mservice_main            |[0m 2023-05-29T16:01:47.690071263Z     self.send(msg)
[33mservice_main            |[0m 2023-05-29T16:01:47.690119727Z   File "/usr/lib/python3.10/http/client.py", line 975, in send
[33mservice_main            |[0m 2023-05-29T16:01:47.690127117Z     self.connect()
[33mservice_main            |[0m 2023-05-29T16:01:47.690132540Z   File "/usr/local/lib/python3.10/dist-packages/urllib3/connection.py", line 205, in connect
[33mservice_main            |[0m 2023-05-29T16:01:47.690138250Z     conn = self._new_conn()
[32mservice_presentation    |[0m 2023-05-29T16:01:17.001876743Z INFO:     Will watch for changes in these directories: ['/']
[32mservice_presentation    |[0m 2023-05-29T16:01:17.002540519Z INFO:     Uvicorn running on http://0.0.0.0:8082 (Press CTRL+C to quit)
[32mservice_presentation    |[0m 2023-05-29T16:01:17.003343581Z INFO:     Started reloader process [1] using WatchFiles
[32mservice_presentation    |[0m 2023-05-29T16:01:18.152013482Z INFO:     Started server process [9]
[32mservice_presentation    |[0m 2023-05-29T16:01:18.152040646Z INFO:     Waiting for application startup.
[32mservice_presentation    |[0m 2023-05-29T16:01:18.158924898Z INFO:     Application startup complete.
[32mservice_presentation    |[0m 2023-05-29T16:01:25.752874564Z <class 'list'>
[32mservice_presentation    |[0m 2023-05-29T16:01:25.752902436Z INFO:     172.18.0.4:45390 - "GET /presentations/First%20Presentation HTTP/1.1" 200 OK
[32mservice_presentation    |[0m 2023-05-29T16:01:27.099239804Z INFO:     172.18.0.4:45398 - "GET /presentations/First%20Presentation HTTP/1.1" 200 OK
[32mservice_presentation    |[0m 2023-05-29T16:01:28.343578139Z INFO:     172.18.0.4:45406 - "GET /presentations/First%20Presentation HTTP/1.1" 200 OK
[32mservice_presentation    |[0m 2023-05-29T16:01:47.609010579Z INFO:     172.18.0.4:45414 - "GET /presentations/First%20Presentation HTTP/1.1" 200 OK
[32mservice_presentation    |[0m 2023-05-29T16:01:51.707282126Z INFO:     172.18.0.4:45420 - "GET /presentations/First%20Presentation HTTP/1.1" 200 OK
[32mservice_presentation    |[0m 2023-05-29T16:01:55.495577332Z INFO:     172.18.0.4:45426 - "GET /presentations/First%20Presentation HTTP/1.1" 200 OK
[32mservice_presentation    |[0m 2023-05-29T16:01:57.400454429Z INFO:     172.18.0.4:45432 - "GET /presentations/First%20Presentation HTTP/1.1" 200 OK
[32mservice_presentation    |[0m 2023-05-29T16:01:59.108868972Z INFO:     172.18.0.4:45438 - "GET /presentations/First%20Presentation HTTP/1.1" 200 OK
[32mservice_presentation    |[0m 2023-05-29T16:02:00.059173830Z INFO:     172.18.0.4:45444 - "GET /presentations/First%20Presentation HTTP/1.1" 200 OK
[32mservice_presentation    |[0m 2023-05-29T16:02:01.150601147Z INFO:     172.18.0.4:45450 - "GET /presentations/First%20Presentation HTTP/1.1" 200 OK
[32mservice_presentation    |[0m 2023-05-29T16:02:02.998992794Z INFO:     172.18.0.4:45456 - "GET /presentations/First%20Presentation HTTP/1.1" 200 OK
[32mservice_presentation    |[0m 2023-05-29T16:02:05.544860010Z INFO:     172.18.0.4:45462 - "GET /presentations/First%20Presentation HTTP/1.1" 200 OK
[32mservice_presentation    |[0m 2023-05-29T16:02:07.578920449Z INFO:     172.18.0.4:45468 - "GET /presentations/First%20Presentation HTTP/1.1" 200 OK
[32mservice_presentation    |[0m 2023-05-29T16:02:09.506200726Z INFO:     172.18.0.4:45474 - "GET /presentations/First%20Presentation HTTP/1.1" 200 OK
[32mservice_presentation    |[0m 2023-05-29T16:02:10.893139446Z INFO:     172.18.0.4:45480 - "GET /presentations/First%20Presentation HTTP/1.1" 200 OK
[32mservice_presentation    |[0m 2023-05-29T16:02:16.638878020Z INFO:     172.18.0.4:45486 - "GET /presentations/First%20Presentation HTTP/1.1" 200 OK
[32mservice_presentation    |[0m 2023-05-29T16:02:19.997879488Z INFO:     172.18.0.4:45492 - "GET /presentations/First%20Presentation HTTP/1.1" 200 OK
[32mservice_presentation    |[0m 2023-05-29T16:02:26.250334954Z INFO:     172.18.0.4:45500 - "GET /presentations/First%20Presentation HTTP/1.1" 200 OK
[32mservice_presentation    |[0m 2023-05-29T16:02:28.048177262Z INFO:     172.18.0.4:45508 - "GET /presentations/First%20Presentation HTTP/1.1" 200 OK
[33mservice_main            |[0m 2023-05-29T16:01:47.690219454Z   File "/usr/local/lib/python3.10/dist-packages/urllib3/connection.py", line 186, in _new_conn
[33mservice_main            |[0m 2023-05-29T16:01:47.690230426Z     raise NewConnectionError(
[33mservice_main            |[0m 2023-05-29T16:01:47.690453348Z urllib3.exceptions.NewConnectionError: <urllib3.connection.HTTPConnection object at 0x7f6c5a4c30a0>: Failed to establish a new connection: [Errno -2] Name or service not known
[33mservice_main            |[0m 2023-05-29T16:01:47.690476402Z 
[33mservice_main            |[0m 2023-05-29T16:01:47.690482544Z During handling of the above exception, another exception occurred:
[33mservice_main            |[0m 2023-05-29T16:01:47.690487724Z 
[33mservice_main            |[0m 2023-05-29T16:01:47.690492704Z Traceback (most recent call last):
[33mservice_main            |[0m 2023-05-29T16:01:47.691186169Z   File "/usr/local/lib/python3.10/dist-packages/requests/adapters.py", line 489, in send
[33mservice_main            |[0m 2023-05-29T16:01:47.691720212Z     resp = conn.urlopen(
[33mservice_main            |[0m 2023-05-29T16:01:47.692063319Z   File "/usr/local/lib/python3.10/dist-packages/urllib3/connectionpool.py", line 787, in urlopen
[33mservice_main            |[0m 2023-05-29T16:01:47.692080440Z     retries = retries.increment(
[33mservice_main            |[0m 2023-05-29T16:01:47.692086748Z   File "/usr/local/lib/python3.10/dist-packages/urllib3/util/retry.py", line 592, in increment
[33mservice_main            |[0m 2023-05-29T16:01:47.692092250Z     raise MaxRetryError(_pool, url, error or ResponseError(cause))
[33mservice_main            |[0m 2023-05-29T16:01:47.694780176Z urllib3.exceptions.MaxRetryError: HTTPConnectionPool(host='service_author', port=8081): Max retries exceeded with url: /authors/1 (Caused by NewConnectionError('<urllib3.connection.HTTPConnection object at 0x7f6c5a4c30a0>: Failed to establish a new connection: [Errno -2] Name or service not known'))
[33mservice_main            |[0m 2023-05-29T16:01:47.694819499Z 
[33mservice_main            |[0m 2023-05-29T16:01:47.694826368Z During handling of the above exception, another exception occurred:
[33mservice_main            |[0m 2023-05-29T16:01:47.694831879Z 
[33mservice_main            |[0m 2023-05-29T16:01:47.694912899Z Traceback (most recent call last):
[33mservice_main            |[0m 2023-05-29T16:01:47.694943330Z   File "/./service_main.py", line 78, in get_author
[33mservice_main            |[0m 2023-05-29T16:01:47.694978389Z     response_author = requests.get("http://" + service_author + "/authors/" + str(id))
[33mservice_main            |[0m 2023-05-29T16:01:47.699576437Z   File "/usr/local/lib/python3.10/dist-packages/requests/api.py", line 73, in get
[33mservice_main            |[0m 2023-05-29T16:01:47.699619712Z     return request("get", url, params=params, **kwargs)
[33mservice_main            |[0m 2023-05-29T16:01:47.699628700Z   File "/usr/local/lib/python3.10/dist-packages/requests/api.py", line 59, in request
[33mservice_main            |[0m 2023-05-29T16:01:47.699635748Z     return session.request(method=method, url=url, **kwargs)
[33mservice_main            |[0m 2023-05-29T16:01:47.699642099Z   File "/usr/local/lib/python3.10/dist-packages/requests/sessions.py", line 587, in request
[33mservice_main            |[0m 2023-05-29T16:01:47.699648454Z     resp = self.send(prep, **send_kwargs)
[33mservice_main            |[0m 2023-05-29T16:01:47.699654433Z   File "/usr/local/lib/python3.10/dist-packages/requests/sessions.py", line 701, in send
[33mservice_main            |[0m 2023-05-29T16:01:47.699660572Z     r = adapter.send(request, **kwargs)
[33mservice_main            |[0m 2023-05-29T16:01:47.699666416Z   File "/usr/local/lib/python3.10/dist-packages/requests/adapters.py", line 565, in send
[33mservice_main            |[0m 2023-05-29T16:01:47.699673158Z     raise ConnectionError(e, request=request)
[33mservice_main            |[0m 2023-05-29T16:01:47.699679855Z requests.exceptions.ConnectionError: HTTPConnectionPool(host='service_author', port=8081): Max retries exceeded with url: /authors/1 (Caused by NewConnectionError('<urllib3.connection.HTTPConnection object at 0x7f6c5a4c30a0>: Failed to establish a new connection: [Errno -2] Name or service not known'))
[33mservice_main            |[0m 2023-05-29T16:01:47.699688006Z 
[33mservice_main            |[0m 2023-05-29T16:01:47.699693549Z During handling of the above exception, another exception occurred:
[33mservice_main            |[0m 2023-05-29T16:01:47.699699584Z 
[33mservice_main            |[0m 2023-05-29T16:01:47.699705161Z Traceback (most recent call last):
[33mservice_main            |[0m 2023-05-29T16:01:47.699710908Z   File "/usr/lib/python3.10/logging/__init__.py", line 1100, in emit
[33mservice_main            |[0m 2023-05-29T16:01:47.699716871Z     msg = self.format(record)
[33mservice_main            |[0m 2023-05-29T16:01:47.699743957Z   File "/usr/lib/python3.10/logging/__init__.py", line 943, in format
[33mservice_main            |[0m 2023-05-29T16:01:47.699750886Z     return fmt.format(record)
[33mservice_main            |[0m 2023-05-29T16:01:47.699756663Z   File "/usr/lib/python3.10/logging/__init__.py", line 678, in format
[33mservice_main            |[0m 2023-05-29T16:01:47.699762748Z     record.message = record.getMessage()
[33mservice_main            |[0m 2023-05-29T16:01:47.699768183Z   File "/usr/lib/python3.10/logging/__init__.py", line 368, in getMessage
[33mservice_main            |[0m 2023-05-29T16:01:47.699773912Z     msg = msg % self.args
[33mservice_main            |[0m 2023-05-29T16:01:47.699779738Z TypeError: not all arguments converted during string formatting
[33mservice_main            |[0m 2023-05-29T16:01:47.699785542Z Call stack:
[33mservice_main            |[0m 2023-05-29T16:01:47.738137111Z   File "<string>", line 1, in <module>
[33mservice_main            |[0m 2023-05-29T16:01:47.740221157Z   File "/usr/lib/python3.10/multiprocessing/spawn.py", line 116, in spawn_main
[33mservice_main            |[0m 2023-05-29T16:01:47.740385958Z     exitcode = _main(fd, parent_sentinel)
[33mservice_main            |[0m 2023-05-29T16:01:47.742839357Z   File "/usr/lib/python3.10/multiprocessing/spawn.py", line 129, in _main
[33mservice_main            |[0m 2023-05-29T16:01:47.742874382Z     return self._bootstrap(parent_sentinel)
[33mservice_main            |[0m 2023-05-29T16:01:47.742880438Z   File "/usr/lib/python3.10/multiprocessing/process.py", line 314, in _bootstrap
[33mservice_main            |[0m 2023-05-29T16:01:47.742885743Z     self.run()
[33mservice_main            |[0m 2023-05-29T16:01:47.742890486Z   File "/usr/lib/python3.10/multiprocessing/process.py", line 108, in run
[33mservice_main            |[0m 2023-05-29T16:01:47.742895517Z     self._target(*self._args, **self._kwargs)
[33mservice_main            |[0m 2023-05-29T16:01:47.742900609Z   File "/usr/local/lib/python3.10/dist-packages/uvicorn/_subprocess.py", line 76, in subprocess_started
[33mservice_main            |[0m 2023-05-29T16:01:47.742905534Z     target(sockets=sockets)
[33mservice_main            |[0m 2023-05-29T16:01:47.742909792Z   File "/usr/local/lib/python3.10/dist-packages/uvicorn/server.py", line 60, in run
[33mservice_main            |[0m 2023-05-29T16:01:47.742914570Z     return asyncio.run(self.serve(sockets=sockets))
[33mservice_main            |[0m 2023-05-29T16:01:47.742920151Z   File "/usr/lib/python3.10/asyncio/runners.py", line 44, in run
[33mservice_main            |[0m 2023-05-29T16:01:47.742925979Z     return loop.run_until_complete(main)
[33mservice_main            |[0m 2023-05-29T16:01:47.742931264Z   File "/usr/lib/python3.10/asyncio/base_events.py", line 633, in run_until_complete
[33mservice_main            |[0m 2023-05-29T16:01:47.742936750Z     self.run_forever()
[33mservice_main            |[0m 2023-05-29T16:01:47.746650592Z   File "/usr/lib/python3.10/asyncio/base_events.py", line 600, in run_forever
[33mservice_main            |[0m 2023-05-29T16:01:47.746680244Z     self._run_once()
[33mservice_main            |[0m 2023-05-29T16:01:47.746684502Z   File "/usr/lib/python3.10/asyncio/base_events.py", line 1896, in _run_once
[33mservice_main            |[0m 2023-05-29T16:01:47.746688568Z     handle._run()
[33mservice_main            |[0m 2023-05-29T16:01:47.746693505Z   File "/usr/lib/python3.10/asyncio/events.py", line 80, in _run
[33mservice_main            |[0m 2023-05-29T16:01:47.746813991Z     self._context.run(self._callback, *self._args)
[33mservice_main            |[0m 2023-05-29T16:01:47.746822634Z   File "/usr/local/lib/python3.10/dist-packages/uvicorn/protocols/http/httptools_impl.py", line 419, in run_asgi
[33mservice_main            |[0m 2023-05-29T16:01:47.752487459Z     result = await app(  # type: ignore[func-returns-value]
[33mservice_main            |[0m 2023-05-29T16:01:47.752514080Z   File "/usr/local/lib/python3.10/dist-packages/uvicorn/middleware/proxy_headers.py", line 78, in __call__
[33mservice_main            |[0m 2023-05-29T16:01:47.752518590Z     return await self.app(scope, receive, send)
[33mservice_main            |[0m 2023-05-29T16:01:47.752521665Z   File "/usr/local/lib/python3.10/dist-packages/fastapi/applications.py", line 271, in __call__
[33mservice_main            |[0m 2023-05-29T16:01:47.752524874Z     await super().__call__(scope, receive, send)
[33mservice_main            |[0m 2023-05-29T16:01:47.752527761Z   File "/usr/local/lib/python3.10/dist-packages/starlette/applications.py", line 118, in __call__
[33mservice_main            |[0m 2023-05-29T16:01:47.752530837Z     await self.middleware_stack(scope, receive, send)
[33mservice_main            |[0m 2023-05-29T16:01:47.752533698Z   File "/usr/local/lib/python3.10/dist-packages/starlette/middleware/errors.py", line 162, in __call__
[33mservice_main            |[0m 2023-05-29T16:01:47.752536720Z     await self.app(scope, receive, _send)
[33mservice_main            |[0m 2023-05-29T16:01:47.752539557Z   File "/usr/local/lib/python3.10/dist-packages/starlette/middleware/exceptions.py", line 68, in __call__
[33mservice_main            |[0m 2023-05-29T16:01:47.752542596Z     await self.app(scope, receive, sender)
[33mservice_main            |[0m 2023-05-29T16:01:47.752545462Z   File "/usr/local/lib/python3.10/dist-packages/fastapi/middleware/asyncexitstack.py", line 18, in __call__
[33mservice_main            |[0m 2023-05-29T16:01:47.752548522Z     await self.app(scope, receive, send)
[33mservice_main            |[0m 2023-05-29T16:01:47.752551358Z   File "/usr/local/lib/python3.10/dist-packages/starlette/routing.py", line 706, in __call__
[33mservice_main            |[0m 2023-05-29T16:01:47.752554411Z     await route.handle(scope, receive, send)
[33mservice_main            |[0m 2023-05-29T16:01:47.752557269Z   File "/usr/local/lib/python3.10/dist-packages/starlette/routing.py", line 276, in handle
[33mservice_main            |[0m 2023-05-29T16:01:47.752560270Z     await self.app(scope, receive, send)
[33mservice_main            |[0m 2023-05-29T16:01:47.752563088Z   File "/usr/local/lib/python3.10/dist-packages/starlette/routing.py", line 66, in app
[33mservice_main            |[0m 2023-05-29T16:01:47.752566124Z     response = await func(request)
[33mservice_main            |[0m 2023-05-29T16:01:47.752588126Z   File "/usr/local/lib/python3.10/dist-packages/fastapi/routing.py", line 237, in app
[33mservice_main            |[0m 2023-05-29T16:01:47.752592785Z     raw_response = await run_endpoint_function(
[33mservice_main            |[0m 2023-05-29T16:01:47.752595800Z   File "/usr/local/lib/python3.10/dist-packages/fastapi/routing.py", line 163, in run_endpoint_function
[33mservice_main            |[0m 2023-05-29T16:01:47.752605057Z     return await dependant.call(**values)
[33mservice_main            |[0m 2023-05-29T16:01:47.752622649Z   File "/./service_main.py", line 110, in read_presentation
[33mservice_main            |[0m 2023-05-29T16:01:47.752628438Z     author = get_author(presentation.author_id)
[33mservice_main            |[0m 2023-05-29T16:01:47.752631432Z   File "/./cbhomemade.py", line 39, in wrapper
[33mservice_main            |[0m 2023-05-29T16:01:47.752634429Z     result = self.func(*args, **kwargs)
[33mservice_main            |[0m 2023-05-29T16:01:47.752769797Z   File "/./service_main.py", line 80, in get_author
[33mservice_main            |[0m 2023-05-29T16:01:47.752779727Z     logging.warning(">>> Error Connecting:", errc)
[33mservice_main            |[0m 2023-05-29T16:01:47.753366168Z Message: '>>> Error Connecting:'
[33mservice_main            |[0m 2023-05-29T16:01:47.753405075Z Arguments: (ConnectionError(MaxRetryError("HTTPConnectionPool(host='service_author', port=8081): Max retries exceeded with url: /authors/1 (Caused by NewConnectionError('<urllib3.connection.HTTPConnection object at 0x7f6c5a4c30a0>: Failed to establish a new connection: [Errno -2] Name or service not known'))")),)
[33mservice_main            |[0m 2023-05-29T16:01:47.754400474Z INFO:     172.18.0.1:59982 - "GET /presentationsAndAuthor/First%20Presentation HTTP/1.1" 500 Internal Server Error
[33mservice_main            |[0m 2023-05-29T16:01:47.785212077Z WARNING:root:Circuit "test-08" is "Status.CLOSED", failures: 1
[33mservice_main            |[0m 2023-05-29T16:01:47.802391475Z WARNING:root:
[33mservice_main            |[0m 2023-05-29T16:01:48.806212690Z WARNING:root:Circuit "test-08" is "Status.CLOSED", failures: 1
[33mservice_main            |[0m 2023-05-29T16:01:48.821089551Z WARNING:root:
[33mservice_main            |[0m 2023-05-29T16:01:49.825123758Z WARNING:root:Circuit "test-08" is "Status.CLOSED", failures: 1
[33mservice_main            |[0m 2023-05-29T16:01:49.846354479Z WARNING:root:
[33mservice_main            |[0m 2023-05-29T16:01:50.855180907Z WARNING:root:Circuit "test-08" is "Status.CLOSED", failures: 1
[33mservice_main            |[0m 2023-05-29T16:01:50.866518299Z WARNING:root:
[33mservice_main            |[0m 2023-05-29T16:01:51.716597431Z --- Logging error ---
[33mservice_main            |[0m 2023-05-29T16:01:51.717520835Z Traceback (most recent call last):
[33mservice_main            |[0m 2023-05-29T16:01:51.717912548Z   File "/usr/local/lib/python3.10/dist-packages/urllib3/connection.py", line 174, in _new_conn
[33mservice_main            |[0m 2023-05-29T16:01:51.717928207Z     conn = connection.create_connection(
[33mservice_main            |[0m 2023-05-29T16:01:51.717934311Z   File "/usr/local/lib/python3.10/dist-packages/urllib3/util/connection.py", line 72, in create_connection
[33mservice_main            |[0m 2023-05-29T16:01:51.717939900Z     for res in socket.getaddrinfo(host, port, family, socket.SOCK_STREAM):
[33mservice_main            |[0m 2023-05-29T16:01:51.718168800Z   File "/usr/lib/python3.10/socket.py", line 955, in getaddrinfo
[33mservice_main            |[0m 2023-05-29T16:01:51.718317617Z     for res in _socket.getaddrinfo(host, port, family, type, proto, flags):
[33mservice_main            |[0m 2023-05-29T16:01:51.718553117Z socket.gaierror: [Errno -2] Name or service not known
[33mservice_main            |[0m 2023-05-29T16:01:51.718628713Z 
[33mservice_main            |[0m 2023-05-29T16:01:51.718653241Z During handling of the above exception, another exception occurred:
[33mservice_main            |[0m 2023-05-29T16:01:51.718659283Z 
[33mservice_main            |[0m 2023-05-29T16:01:51.719032967Z Traceback (most recent call last):
[33mservice_main            |[0m 2023-05-29T16:01:51.719565096Z   File "/usr/local/lib/python3.10/dist-packages/urllib3/connectionpool.py", line 703, in urlopen
[33mservice_main            |[0m 2023-05-29T16:01:51.719585566Z     httplib_response = self._make_request(
[33mservice_main            |[0m 2023-05-29T16:01:51.720113896Z   File "/usr/local/lib/python3.10/dist-packages/urllib3/connectionpool.py", line 398, in _make_request
[33mservice_main            |[0m 2023-05-29T16:01:51.720339764Z     conn.request(method, url, **httplib_request_kw)
[33mservice_main            |[0m 2023-05-29T16:01:51.720856897Z   File "/usr/local/lib/python3.10/dist-packages/urllib3/connection.py", line 239, in request
[33mservice_main            |[0m 2023-05-29T16:01:51.720875758Z     super(HTTPConnection, self).request(method, url, body=body, headers=headers)
[33mservice_main            |[0m 2023-05-29T16:01:51.720882578Z   File "/usr/lib/python3.10/http/client.py", line 1282, in request
[33mservice_main            |[0m 2023-05-29T16:01:51.720916795Z     self._send_request(method, url, body, headers, encode_chunked)
[33mservice_main            |[0m 2023-05-29T16:01:51.721442929Z   File "/usr/lib/python3.10/http/client.py", line 1328, in _send_request
[33mservice_main            |[0m 2023-05-29T16:01:51.721479983Z     self.endheaders(body, encode_chunked=encode_chunked)
[33mservice_main            |[0m 2023-05-29T16:01:51.721487825Z   File "/usr/lib/python3.10/http/client.py", line 1277, in endheaders
[33mservice_main            |[0m 2023-05-29T16:01:51.721493176Z     self._send_output(message_body, encode_chunked=encode_chunked)
[33mservice_main            |[0m 2023-05-29T16:01:51.721497663Z   File "/usr/lib/python3.10/http/client.py", line 1037, in _send_output
[33mservice_main            |[0m 2023-05-29T16:01:51.721502368Z     self.send(msg)
[33mservice_main            |[0m 2023-05-29T16:01:51.721506688Z   File "/usr/lib/python3.10/http/client.py", line 975, in send
[33mservice_main            |[0m 2023-05-29T16:01:51.721511472Z     self.connect()
[33mservice_main            |[0m 2023-05-29T16:01:51.721516010Z   File "/usr/local/lib/python3.10/dist-packages/urllib3/connection.py", line 205, in connect
[33mservice_main            |[0m 2023-05-29T16:01:51.721520941Z     conn = self._new_conn()
[33mservice_main            |[0m 2023-05-29T16:01:51.721525648Z   File "/usr/local/lib/python3.10/dist-packages/urllib3/connection.py", line 186, in _new_conn
[33mservice_main            |[0m 2023-05-29T16:01:51.721530698Z     raise NewConnectionError(
[33mservice_main            |[0m 2023-05-29T16:01:51.721535466Z urllib3.exceptions.NewConnectionError: <urllib3.connection.HTTPConnection object at 0x7f6c59a7cb20>: Failed to establish a new connection: [Errno -2] Name or service not known
[33mservice_main            |[0m 2023-05-29T16:01:51.721541149Z 
[33mservice_main            |[0m 2023-05-29T16:01:51.721545621Z During handling of the above exception, another exception occurred:
[33mservice_main            |[0m 2023-05-29T16:01:51.721550116Z 
[33mservice_main            |[0m 2023-05-29T16:01:51.721895688Z Traceback (most recent call last):
[33mservice_main            |[0m 2023-05-29T16:01:51.722461107Z   File "/usr/local/lib/python3.10/dist-packages/requests/adapters.py", line 489, in send
[33mservice_main            |[0m 2023-05-29T16:01:51.722485736Z     resp = conn.urlopen(
[33mservice_main            |[0m 2023-05-29T16:01:51.722489201Z   File "/usr/local/lib/python3.10/dist-packages/urllib3/connectionpool.py", line 787, in urlopen
[33mservice_main            |[0m 2023-05-29T16:01:51.722492299Z     retries = retries.increment(
[33mservice_main            |[0m 2023-05-29T16:01:51.722495047Z   File "/usr/local/lib/python3.10/dist-packages/urllib3/util/retry.py", line 592, in increment
[33mservice_main            |[0m 2023-05-29T16:01:51.722498552Z     raise MaxRetryError(_pool, url, error or ResponseError(cause))
[33mservice_main            |[0m 2023-05-29T16:01:51.722680462Z urllib3.exceptions.MaxRetryError: HTTPConnectionPool(host='service_author', port=8081): Max retries exceeded with url: /authors/1 (Caused by NewConnectionError('<urllib3.connection.HTTPConnection object at 0x7f6c59a7cb20>: Failed to establish a new connection: [Errno -2] Name or service not known'))
[33mservice_main            |[0m 2023-05-29T16:01:51.722885050Z 
[33mservice_main            |[0m 2023-05-29T16:01:51.722899530Z During handling of the above exception, another exception occurred:
[33mservice_main            |[0m 2023-05-29T16:01:51.722906361Z 
[33mservice_main            |[0m 2023-05-29T16:01:51.723178395Z Traceback (most recent call last):
[33mservice_main            |[0m 2023-05-29T16:01:51.723509157Z   File "/./service_main.py", line 78, in get_author
[33mservice_main            |[0m 2023-05-29T16:01:51.723523606Z     response_author = requests.get("http://" + service_author + "/authors/" + str(id))
[33mservice_main            |[0m 2023-05-29T16:01:51.723806442Z   File "/usr/local/lib/python3.10/dist-packages/requests/api.py", line 73, in get
[33mservice_main            |[0m 2023-05-29T16:01:51.723821152Z     return request("get", url, params=params, **kwargs)
[33mservice_main            |[0m 2023-05-29T16:01:51.723940357Z   File "/usr/local/lib/python3.10/dist-packages/requests/api.py", line 59, in request
[33mservice_main            |[0m 2023-05-29T16:01:51.723953444Z     return session.request(method=method, url=url, **kwargs)
[33mservice_main            |[0m 2023-05-29T16:01:51.724182419Z   File "/usr/local/lib/python3.10/dist-packages/requests/sessions.py", line 587, in request
[33mservice_main            |[0m 2023-05-29T16:01:51.724197114Z     resp = self.send(prep, **send_kwargs)
[33mservice_main            |[0m 2023-05-29T16:01:51.724316577Z   File "/usr/local/lib/python3.10/dist-packages/requests/sessions.py", line 701, in send
[33mservice_main            |[0m 2023-05-29T16:01:51.724330539Z     r = adapter.send(request, **kwargs)
[33mservice_main            |[0m 2023-05-29T16:01:51.724742917Z   File "/usr/local/lib/python3.10/dist-packages/requests/adapters.py", line 565, in send
[33mservice_main            |[0m 2023-05-29T16:01:51.724765207Z     raise ConnectionError(e, request=request)
[33mservice_main            |[0m 2023-05-29T16:01:51.725075233Z requests.exceptions.ConnectionError: HTTPConnectionPool(host='service_author', port=8081): Max retries exceeded with url: /authors/1 (Caused by NewConnectionError('<urllib3.connection.HTTPConnection object at 0x7f6c59a7cb20>: Failed to establish a new connection: [Errno -2] Name or service not known'))
[33mservice_main            |[0m 2023-05-29T16:01:51.725394795Z 
[33mservice_main            |[0m 2023-05-29T16:01:51.725409474Z During handling of the above exception, another exception occurred:
[33mservice_main            |[0m 2023-05-29T16:01:51.725415399Z 
[33mservice_main            |[0m 2023-05-29T16:01:51.725632909Z Traceback (most recent call last):
[33mservice_main            |[0m 2023-05-29T16:01:51.725909945Z   File "/usr/lib/python3.10/logging/__init__.py", line 1100, in emit
[33mservice_main            |[0m 2023-05-29T16:01:51.725968309Z     msg = self.format(record)
[33mservice_main            |[0m 2023-05-29T16:01:51.726248617Z   File "/usr/lib/python3.10/logging/__init__.py", line 943, in format
[33mservice_main            |[0m 2023-05-29T16:01:51.726262190Z     return fmt.format(record)
[33mservice_main            |[0m 2023-05-29T16:01:51.726510856Z   File "/usr/lib/python3.10/logging/__init__.py", line 678, in format
[33mservice_main            |[0m 2023-05-29T16:01:51.726526093Z     record.message = record.getMessage()
[33mservice_main            |[0m 2023-05-29T16:01:51.726645605Z   File "/usr/lib/python3.10/logging/__init__.py", line 368, in getMessage
[33mservice_main            |[0m 2023-05-29T16:01:51.726658464Z     msg = msg % self.args
[33mservice_main            |[0m 2023-05-29T16:01:51.726787085Z TypeError: not all arguments converted during string formatting
[33mservice_main            |[0m 2023-05-29T16:01:51.727050215Z Call stack:
[33mservice_main            |[0m 2023-05-29T16:01:51.728587472Z   File "<string>", line 1, in <module>
[33mservice_main            |[0m 2023-05-29T16:01:51.728970516Z   File "/usr/lib/python3.10/multiprocessing/spawn.py", line 116, in spawn_main
[33mservice_main            |[0m 2023-05-29T16:01:51.728997053Z     exitcode = _main(fd, parent_sentinel)
[33mservice_main            |[0m 2023-05-29T16:01:51.729198413Z   File "/usr/lib/python3.10/multiprocessing/spawn.py", line 129, in _main
[33mservice_main            |[0m 2023-05-29T16:01:51.729212074Z     return self._bootstrap(parent_sentinel)
[33mservice_main            |[0m 2023-05-29T16:01:51.729600412Z   File "/usr/lib/python3.10/multiprocessing/process.py", line 314, in _bootstrap
[33mservice_main            |[0m 2023-05-29T16:01:51.729617541Z     self.run()
[33mservice_main            |[0m 2023-05-29T16:01:51.729864958Z   File "/usr/lib/python3.10/multiprocessing/process.py", line 108, in run
[33mservice_main            |[0m 2023-05-29T16:01:51.729880100Z     self._target(*self._args, **self._kwargs)
[33mservice_main            |[0m 2023-05-29T16:01:51.730151073Z   File "/usr/local/lib/python3.10/dist-packages/uvicorn/_subprocess.py", line 76, in subprocess_started
[33mservice_main            |[0m 2023-05-29T16:01:51.730252582Z     target(sockets=sockets)
[33mservice_main            |[0m 2023-05-29T16:01:51.730446430Z   File "/usr/local/lib/python3.10/dist-packages/uvicorn/server.py", line 60, in run
[33mservice_main            |[0m 2023-05-29T16:01:51.730469486Z     return asyncio.run(self.serve(sockets=sockets))
[33mservice_main            |[0m 2023-05-29T16:01:51.730781866Z   File "/usr/lib/python3.10/asyncio/runners.py", line 44, in run
[33mservice_main            |[0m 2023-05-29T16:01:51.730799085Z     return loop.run_until_complete(main)
[33mservice_main            |[0m 2023-05-29T16:01:51.731116227Z   File "/usr/lib/python3.10/asyncio/base_events.py", line 633, in run_until_complete
[33mservice_main            |[0m 2023-05-29T16:01:51.731199171Z     self.run_forever()
[33mservice_main            |[0m 2023-05-29T16:01:51.731454477Z   File "/usr/lib/python3.10/asyncio/base_events.py", line 600, in run_forever
[33mservice_main            |[0m 2023-05-29T16:01:51.731478461Z     self._run_once()
[33mservice_main            |[0m 2023-05-29T16:01:51.731697279Z   File "/usr/lib/python3.10/asyncio/base_events.py", line 1896, in _run_once
[33mservice_main            |[0m 2023-05-29T16:01:51.731764256Z     handle._run()
[33mservice_main            |[0m 2023-05-29T16:01:51.731951039Z   File "/usr/lib/python3.10/asyncio/events.py", line 80, in _run
[33mservice_main            |[0m 2023-05-29T16:01:51.731964911Z     self._context.run(self._callback, *self._args)
[33mservice_main            |[0m 2023-05-29T16:01:51.732117261Z   File "/usr/local/lib/python3.10/dist-packages/uvicorn/protocols/http/httptools_impl.py", line 419, in run_asgi
[33mservice_main            |[0m 2023-05-29T16:01:51.732131327Z     result = await app(  # type: ignore[func-returns-value]
[33mservice_main            |[0m 2023-05-29T16:01:51.732349839Z   File "/usr/local/lib/python3.10/dist-packages/uvicorn/middleware/proxy_headers.py", line 78, in __call__
[33mservice_main            |[0m 2023-05-29T16:01:51.732365361Z     return await self.app(scope, receive, send)
[33mservice_main            |[0m 2023-05-29T16:01:51.732560301Z   File "/usr/local/lib/python3.10/dist-packages/fastapi/applications.py", line 271, in __call__
[33mservice_main            |[0m 2023-05-29T16:01:51.732573868Z     await super().__call__(scope, receive, send)
[33mservice_main            |[0m 2023-05-29T16:01:51.732851908Z   File "/usr/local/lib/python3.10/dist-packages/starlette/applications.py", line 118, in __call__
[33mservice_main            |[0m 2023-05-29T16:01:51.733028622Z     await self.middleware_stack(scope, receive, send)
[33mservice_main            |[0m 2023-05-29T16:01:51.733151209Z   File "/usr/local/lib/python3.10/dist-packages/starlette/middleware/errors.py", line 162, in __call__
[33mservice_main            |[0m 2023-05-29T16:01:51.733333746Z     await self.app(scope, receive, _send)
[33mservice_main            |[0m 2023-05-29T16:01:51.733482514Z   File "/usr/local/lib/python3.10/dist-packages/starlette/middleware/exceptions.py", line 68, in __call__
[33mservice_main            |[0m 2023-05-29T16:01:51.733527883Z     await self.app(scope, receive, sender)
[33mservice_main            |[0m 2023-05-29T16:01:51.733534905Z   File "/usr/local/lib/python3.10/dist-packages/fastapi/middleware/asyncexitstack.py", line 18, in __call__
[33mservice_main            |[0m 2023-05-29T16:01:51.733558718Z     await self.app(scope, receive, send)
[33mservice_main            |[0m 2023-05-29T16:01:51.733656339Z   File "/usr/local/lib/python3.10/dist-packages/starlette/routing.py", line 706, in __call__
[33mservice_main            |[0m 2023-05-29T16:01:51.733663118Z     await route.handle(scope, receive, send)
[33mservice_main            |[0m 2023-05-29T16:01:51.733771606Z   File "/usr/local/lib/python3.10/dist-packages/starlette/routing.py", line 276, in handle
[33mservice_main            |[0m 2023-05-29T16:01:51.733785623Z     await self.app(scope, receive, send)
[33mservice_main            |[0m 2023-05-29T16:01:51.734066900Z   File "/usr/local/lib/python3.10/dist-packages/starlette/routing.py", line 66, in app
[33mservice_main            |[0m 2023-05-29T16:01:51.734085038Z     response = await func(request)
[33mservice_main            |[0m 2023-05-29T16:01:51.734362701Z   File "/usr/local/lib/python3.10/dist-packages/fastapi/routing.py", line 237, in app
[33mservice_main            |[0m 2023-05-29T16:01:51.734461277Z     raw_response = await run_endpoint_function(
[33mservice_main            |[0m 2023-05-29T16:01:51.734879579Z   File "/usr/local/lib/python3.10/dist-packages/fastapi/routing.py", line 163, in run_endpoint_function
[33mservice_main            |[0m 2023-05-29T16:01:51.734894809Z     return await dependant.call(**values)
[33mservice_main            |[0m 2023-05-29T16:01:51.734901269Z   File "/./service_main.py", line 110, in read_presentation
[33mservice_main            |[0m 2023-05-29T16:01:51.734906477Z     author = get_author(presentation.author_id)
[33mservice_main            |[0m 2023-05-29T16:01:51.734911295Z   File "/./cbhomemade.py", line 39, in wrapper
[33mservice_main            |[0m 2023-05-29T16:01:51.734915930Z     result = self.func(*args, **kwargs)
[33mservice_main            |[0m 2023-05-29T16:01:51.734921193Z   File "/./service_main.py", line 80, in get_author
[33mservice_main            |[0m 2023-05-29T16:01:51.734926575Z     logging.warning(">>> Error Connecting:", errc)
[33mservice_main            |[0m 2023-05-29T16:01:51.735080976Z Message: '>>> Error Connecting:'
[33mservice_main            |[0m 2023-05-29T16:01:51.735096500Z Arguments: (ConnectionError(MaxRetryError("HTTPConnectionPool(host='service_author', port=8081): Max retries exceeded with url: /authors/1 (Caused by NewConnectionError('<urllib3.connection.HTTPConnection object at 0x7f6c59a7cb20>: Failed to establish a new connection: [Errno -2] Name or service not known'))")),)
[33mservice_main            |[0m 2023-05-29T16:01:51.736101010Z INFO:     172.18.0.1:59988 - "GET /presentationsAndAuthor/First%20Presentation HTTP/1.1" 500 Internal Server Error
[33mservice_main            |[0m 2023-05-29T16:01:51.871885103Z WARNING:root:Circuit "test-08" is "Status.CLOSED", failures: 2
[33mservice_main            |[0m 2023-05-29T16:01:51.890906655Z WARNING:root:
[33mservice_main            |[0m 2023-05-29T16:01:52.893924740Z WARNING:root:Circuit "test-08" is "Status.CLOSED", failures: 2
[33mservice_main            |[0m 2023-05-29T16:01:52.911030803Z WARNING:root:
[33mservice_main            |[0m 2023-05-29T16:01:53.915072596Z WARNING:root:Circuit "test-08" is "Status.CLOSED", failures: 2
[33mservice_main            |[0m 2023-05-29T16:01:53.929004319Z WARNING:root:
[33mservice_main            |[0m 2023-05-29T16:01:54.933337276Z WARNING:root:Circuit "test-08" is "Status.CLOSED", failures: 2
[33mservice_main            |[0m 2023-05-29T16:01:54.947590711Z WARNING:root:
[33mservice_main            |[0m 2023-05-29T16:01:55.504472111Z --- Logging error ---
[33mservice_main            |[0m 2023-05-29T16:01:55.505671843Z Traceback (most recent call last):
[33mservice_main            |[0m 2023-05-29T16:01:55.506042676Z   File "/usr/local/lib/python3.10/dist-packages/urllib3/connection.py", line 174, in _new_conn
[33mservice_main            |[0m 2023-05-29T16:01:55.506057804Z     conn = connection.create_connection(
[33mservice_main            |[0m 2023-05-29T16:01:55.506393646Z   File "/usr/local/lib/python3.10/dist-packages/urllib3/util/connection.py", line 72, in create_connection
[33mservice_main            |[0m 2023-05-29T16:01:55.506449728Z     for res in socket.getaddrinfo(host, port, family, socket.SOCK_STREAM):
[33mservice_main            |[0m 2023-05-29T16:01:55.506680122Z   File "/usr/lib/python3.10/socket.py", line 955, in getaddrinfo
[33mservice_main            |[0m 2023-05-29T16:01:55.506694227Z     for res in _socket.getaddrinfo(host, port, family, type, proto, flags):
[33mservice_main            |[0m 2023-05-29T16:01:55.506936549Z socket.gaierror: [Errno -2] Name or service not known
[33mservice_main            |[0m 2023-05-29T16:01:55.507064650Z 
[33mservice_main            |[0m 2023-05-29T16:01:55.507077884Z During handling of the above exception, another exception occurred:
[33mservice_main            |[0m 2023-05-29T16:01:55.507084437Z 
[33mservice_main            |[0m 2023-05-29T16:01:55.507410160Z Traceback (most recent call last):
[33mservice_main            |[0m 2023-05-29T16:01:55.507752730Z   File "/usr/local/lib/python3.10/dist-packages/urllib3/connectionpool.py", line 703, in urlopen
[33mservice_main            |[0m 2023-05-29T16:01:55.507786357Z     httplib_response = self._make_request(
[33mservice_main            |[0m 2023-05-29T16:01:55.508096443Z   File "/usr/local/lib/python3.10/dist-packages/urllib3/connectionpool.py", line 398, in _make_request
[33mservice_main            |[0m 2023-05-29T16:01:55.508141578Z     conn.request(method, url, **httplib_request_kw)
[33mservice_main            |[0m 2023-05-29T16:01:55.508456740Z   File "/usr/local/lib/python3.10/dist-packages/urllib3/connection.py", line 239, in request
[33mservice_main            |[0m 2023-05-29T16:01:55.508476268Z     super(HTTPConnection, self).request(method, url, body=body, headers=headers)
[33mservice_main            |[0m 2023-05-29T16:01:55.508910801Z   File "/usr/lib/python3.10/http/client.py", line 1282, in request
[33mservice_main            |[0m 2023-05-29T16:01:55.508928177Z     self._send_request(method, url, body, headers, encode_chunked)
[33mservice_main            |[0m 2023-05-29T16:01:55.509118500Z   File "/usr/lib/python3.10/http/client.py", line 1328, in _send_request
[33mservice_main            |[0m 2023-05-29T16:01:55.509136453Z     self.endheaders(body, encode_chunked=encode_chunked)
[33mservice_main            |[0m 2023-05-29T16:01:55.509346441Z   File "/usr/lib/python3.10/http/client.py", line 1277, in endheaders
[33mservice_main            |[0m 2023-05-29T16:01:55.509432116Z     self._send_output(message_body, encode_chunked=encode_chunked)
[33mservice_main            |[0m 2023-05-29T16:01:55.509589301Z   File "/usr/lib/python3.10/http/client.py", line 1037, in _send_output
[33mservice_main            |[0m 2023-05-29T16:01:55.509644154Z     self.send(msg)
[33mservice_main            |[0m 2023-05-29T16:01:55.509924712Z   File "/usr/lib/python3.10/http/client.py", line 975, in send
[33mservice_main            |[0m 2023-05-29T16:01:55.509981954Z     self.connect()
[33mservice_main            |[0m 2023-05-29T16:01:55.510256944Z   File "/usr/local/lib/python3.10/dist-packages/urllib3/connection.py", line 205, in connect
[33mservice_main            |[0m 2023-05-29T16:01:55.510272405Z     conn = self._new_conn()
[33mservice_main            |[0m 2023-05-29T16:01:55.510584065Z   File "/usr/local/lib/python3.10/dist-packages/urllib3/connection.py", line 186, in _new_conn
[33mservice_main            |[0m 2023-05-29T16:01:55.510600685Z     raise NewConnectionError(
[33mservice_main            |[0m 2023-05-29T16:01:55.510802472Z urllib3.exceptions.NewConnectionError: <urllib3.connection.HTTPConnection object at 0x7f6c5a4c36d0>: Failed to establish a new connection: [Errno -2] Name or service not known
[33mservice_main            |[0m 2023-05-29T16:01:55.511132100Z 
[33mservice_main            |[0m 2023-05-29T16:01:55.511146682Z During handling of the above exception, another exception occurred:
[33mservice_main            |[0m 2023-05-29T16:01:55.511200539Z 
[33mservice_main            |[0m 2023-05-29T16:01:55.511377528Z Traceback (most recent call last):
[33mservice_main            |[0m 2023-05-29T16:01:55.511747955Z   File "/usr/local/lib/python3.10/dist-packages/requests/adapters.py", line 489, in send
[33mservice_main            |[0m 2023-05-29T16:01:55.511766004Z     resp = conn.urlopen(
[33mservice_main            |[0m 2023-05-29T16:01:55.512185617Z   File "/usr/local/lib/python3.10/dist-packages/urllib3/connectionpool.py", line 787, in urlopen
[33mservice_main            |[0m 2023-05-29T16:01:55.512201214Z     retries = retries.increment(
[33mservice_main            |[0m 2023-05-29T16:01:55.512658315Z   File "/usr/local/lib/python3.10/dist-packages/urllib3/util/retry.py", line 592, in increment
[33mservice_main            |[0m 2023-05-29T16:01:55.512678847Z     raise MaxRetryError(_pool, url, error or ResponseError(cause))
[33mservice_main            |[0m 2023-05-29T16:01:55.513019112Z urllib3.exceptions.MaxRetryError: HTTPConnectionPool(host='service_author', port=8081): Max retries exceeded with url: /authors/1 (Caused by NewConnectionError('<urllib3.connection.HTTPConnection object at 0x7f6c5a4c36d0>: Failed to establish a new connection: [Errno -2] Name or service not known'))
[33mservice_main            |[0m 2023-05-29T16:01:55.513479813Z 
[33mservice_main            |[0m 2023-05-29T16:01:55.513497864Z During handling of the above exception, another exception occurred:
[33mservice_main            |[0m 2023-05-29T16:01:55.513504906Z 
[33mservice_main            |[0m 2023-05-29T16:01:55.513797875Z Traceback (most recent call last):
[33mservice_main            |[0m 2023-05-29T16:01:55.514227565Z   File "/./service_main.py", line 78, in get_author
[33mservice_main            |[0m 2023-05-29T16:01:55.514277713Z     response_author = requests.get("http://" + service_author + "/authors/" + str(id))
[33mservice_main            |[0m 2023-05-29T16:01:55.514730177Z   File "/usr/local/lib/python3.10/dist-packages/requests/api.py", line 73, in get
[33mservice_main            |[0m 2023-05-29T16:01:55.514748994Z     return request("get", url, params=params, **kwargs)
[33mservice_main            |[0m 2023-05-29T16:01:55.515075669Z   File "/usr/local/lib/python3.10/dist-packages/requests/api.py", line 59, in request
[33mservice_main            |[0m 2023-05-29T16:01:55.515090934Z     return session.request(method=method, url=url, **kwargs)
[33mservice_main            |[0m 2023-05-29T16:01:55.515563066Z   File "/usr/local/lib/python3.10/dist-packages/requests/sessions.py", line 587, in request
[33mservice_main            |[0m 2023-05-29T16:01:55.515581749Z     resp = self.send(prep, **send_kwargs)
[33mservice_main            |[0m 2023-05-29T16:01:55.515924257Z   File "/usr/local/lib/python3.10/dist-packages/requests/sessions.py", line 701, in send
[33mservice_main            |[0m 2023-05-29T16:01:55.515939340Z     r = adapter.send(request, **kwargs)
[33mservice_main            |[0m 2023-05-29T16:01:55.516247000Z   File "/usr/local/lib/python3.10/dist-packages/requests/adapters.py", line 565, in send
[33mservice_main            |[0m 2023-05-29T16:01:55.516262322Z     raise ConnectionError(e, request=request)
[33mservice_main            |[0m 2023-05-29T16:01:55.516555960Z requests.exceptions.ConnectionError: HTTPConnectionPool(host='service_author', port=8081): Max retries exceeded with url: /authors/1 (Caused by NewConnectionError('<urllib3.connection.HTTPConnection object at 0x7f6c5a4c36d0>: Failed to establish a new connection: [Errno -2] Name or service not known'))
[33mservice_main            |[0m 2023-05-29T16:01:55.516867500Z 
[33mservice_main            |[0m 2023-05-29T16:01:55.516890319Z During handling of the above exception, another exception occurred:
[33mservice_main            |[0m 2023-05-29T16:01:55.516898422Z 
[33mservice_main            |[0m 2023-05-29T16:01:55.517623959Z Traceback (most recent call last):
[33mservice_main            |[0m 2023-05-29T16:01:55.518009566Z   File "/usr/lib/python3.10/logging/__init__.py", line 1100, in emit
[33mservice_main            |[0m 2023-05-29T16:01:55.518026082Z     msg = self.format(record)
[33mservice_main            |[0m 2023-05-29T16:01:55.518617865Z   File "/usr/lib/python3.10/logging/__init__.py", line 943, in format
[33mservice_main            |[0m 2023-05-29T16:01:55.518638167Z     return fmt.format(record)
[33mservice_main            |[0m 2023-05-29T16:01:55.520606658Z   File "/usr/lib/python3.10/logging/__init__.py", line 678, in format
[33mservice_main            |[0m 2023-05-29T16:01:55.520639572Z     record.message = record.getMessage()
[33mservice_main            |[0m 2023-05-29T16:01:55.520684193Z   File "/usr/lib/python3.10/logging/__init__.py", line 368, in getMessage
[33mservice_main            |[0m 2023-05-29T16:01:55.520691182Z     msg = msg % self.args
[33mservice_main            |[0m 2023-05-29T16:01:55.520694386Z TypeError: not all arguments converted during string formatting
[33mservice_main            |[0m 2023-05-29T16:01:55.520697367Z Call stack:
[33mservice_main            |[0m 2023-05-29T16:01:55.521782974Z   File "<string>", line 1, in <module>
[33mservice_main            |[0m 2023-05-29T16:01:55.522002195Z   File "/usr/lib/python3.10/multiprocessing/spawn.py", line 116, in spawn_main
[33mservice_main            |[0m 2023-05-29T16:01:55.522017002Z     exitcode = _main(fd, parent_sentinel)
[33mservice_main            |[0m 2023-05-29T16:01:55.522345194Z   File "/usr/lib/python3.10/multiprocessing/spawn.py", line 129, in _main
[33mservice_main            |[0m 2023-05-29T16:01:55.522393565Z     return self._bootstrap(parent_sentinel)
[33mservice_main            |[0m 2023-05-29T16:01:55.522936113Z   File "/usr/lib/python3.10/multiprocessing/process.py", line 314, in _bootstrap
[33mservice_main            |[0m 2023-05-29T16:01:55.522956137Z     self.run()
[33mservice_main            |[0m 2023-05-29T16:01:55.523426187Z   File "/usr/lib/python3.10/multiprocessing/process.py", line 108, in run
[33mservice_main            |[0m 2023-05-29T16:01:55.523642246Z     self._target(*self._args, **self._kwargs)
[33mservice_main            |[0m 2023-05-29T16:01:55.523863794Z   File "/usr/local/lib/python3.10/dist-packages/uvicorn/_subprocess.py", line 76, in subprocess_started
[33mservice_main            |[0m 2023-05-29T16:01:55.524028366Z     target(sockets=sockets)
[33mservice_main            |[0m 2023-05-29T16:01:55.524162215Z   File "/usr/local/lib/python3.10/dist-packages/uvicorn/server.py", line 60, in run
[33mservice_main            |[0m 2023-05-29T16:01:55.524265101Z     return asyncio.run(self.serve(sockets=sockets))
[33mservice_main            |[0m 2023-05-29T16:01:55.524485488Z   File "/usr/lib/python3.10/asyncio/runners.py", line 44, in run
[33mservice_main            |[0m 2023-05-29T16:01:55.524498929Z     return loop.run_until_complete(main)
[33mservice_main            |[0m 2023-05-29T16:01:55.524966579Z   File "/usr/lib/python3.10/asyncio/base_events.py", line 633, in run_until_complete
[33mservice_main            |[0m 2023-05-29T16:01:55.524982500Z     self.run_forever()
[33mservice_main            |[0m 2023-05-29T16:01:55.525651909Z   File "/usr/lib/python3.10/asyncio/base_events.py", line 600, in run_forever
[33mservice_main            |[0m 2023-05-29T16:01:55.525699636Z     self._run_once()
[33mservice_main            |[0m 2023-05-29T16:01:55.525773343Z   File "/usr/lib/python3.10/asyncio/base_events.py", line 1896, in _run_once
[33mservice_main            |[0m 2023-05-29T16:01:55.525783393Z     handle._run()
[33mservice_main            |[0m 2023-05-29T16:01:55.525789268Z   File "/usr/lib/python3.10/asyncio/events.py", line 80, in _run
[33mservice_main            |[0m 2023-05-29T16:01:55.525794808Z     self._context.run(self._callback, *self._args)
[33mservice_main            |[0m 2023-05-29T16:01:55.525799896Z   File "/usr/local/lib/python3.10/dist-packages/uvicorn/protocols/http/httptools_impl.py", line 419, in run_asgi
[33mservice_main            |[0m 2023-05-29T16:01:55.525805304Z     result = await app(  # type: ignore[func-returns-value]
[33mservice_main            |[0m 2023-05-29T16:01:55.525810627Z   File "/usr/local/lib/python3.10/dist-packages/uvicorn/middleware/proxy_headers.py", line 78, in __call__
[33mservice_main            |[0m 2023-05-29T16:01:55.525815881Z     return await self.app(scope, receive, send)
[33mservice_main            |[0m 2023-05-29T16:01:55.525820901Z   File "/usr/local/lib/python3.10/dist-packages/fastapi/applications.py", line 271, in __call__
[33mservice_main            |[0m 2023-05-29T16:01:55.525825921Z     await super().__call__(scope, receive, send)
[33mservice_main            |[0m 2023-05-29T16:01:55.525831272Z   File "/usr/local/lib/python3.10/dist-packages/starlette/applications.py", line 118, in __call__
[33mservice_main            |[0m 2023-05-29T16:01:55.525836319Z     await self.middleware_stack(scope, receive, send)
[33mservice_main            |[0m 2023-05-29T16:01:55.525841250Z   File "/usr/local/lib/python3.10/dist-packages/starlette/middleware/errors.py", line 162, in __call__
[33mservice_main            |[0m 2023-05-29T16:01:55.525865639Z     await self.app(scope, receive, _send)
[33mservice_main            |[0m 2023-05-29T16:01:55.525879929Z   File "/usr/local/lib/python3.10/dist-packages/starlette/middleware/exceptions.py", line 68, in __call__
[33mservice_main            |[0m 2023-05-29T16:01:55.525894132Z     await self.app(scope, receive, sender)
[33mservice_main            |[0m 2023-05-29T16:01:55.525905858Z   File "/usr/local/lib/python3.10/dist-packages/fastapi/middleware/asyncexitstack.py", line 18, in __call__
[33mservice_main            |[0m 2023-05-29T16:01:55.525913864Z     await self.app(scope, receive, send)
[33mservice_main            |[0m 2023-05-29T16:01:55.525919749Z   File "/usr/local/lib/python3.10/dist-packages/starlette/routing.py", line 706, in __call__
[33mservice_main            |[0m 2023-05-29T16:01:55.525926659Z     await route.handle(scope, receive, send)
[33mservice_main            |[0m 2023-05-29T16:01:55.525932677Z   File "/usr/local/lib/python3.10/dist-packages/starlette/routing.py", line 276, in handle
[33mservice_main            |[0m 2023-05-29T16:01:55.525938525Z     await self.app(scope, receive, send)
[33mservice_main            |[0m 2023-05-29T16:01:55.525944355Z   File "/usr/local/lib/python3.10/dist-packages/starlette/routing.py", line 66, in app
[33mservice_main            |[0m 2023-05-29T16:01:55.525950339Z     response = await func(request)
[33mservice_main            |[0m 2023-05-29T16:01:55.525955549Z   File "/usr/local/lib/python3.10/dist-packages/fastapi/routing.py", line 237, in app
[33mservice_main            |[0m 2023-05-29T16:01:55.525961593Z     raw_response = await run_endpoint_function(
[33mservice_main            |[0m 2023-05-29T16:01:55.525967211Z   File "/usr/local/lib/python3.10/dist-packages/fastapi/routing.py", line 163, in run_endpoint_function
[33mservice_main            |[0m 2023-05-29T16:01:55.525975513Z     return await dependant.call(**values)
[33mservice_main            |[0m 2023-05-29T16:01:55.526023573Z   File "/./service_main.py", line 110, in read_presentation
[33mservice_main            |[0m 2023-05-29T16:01:55.526032866Z     author = get_author(presentation.author_id)
[33mservice_main            |[0m 2023-05-29T16:01:55.526038084Z   File "/./cbhomemade.py", line 39, in wrapper
[33mservice_main            |[0m 2023-05-29T16:01:55.526043148Z     result = self.func(*args, **kwargs)
[33mservice_main            |[0m 2023-05-29T16:01:55.526047921Z   File "/./service_main.py", line 80, in get_author
[33mservice_main            |[0m 2023-05-29T16:01:55.526052904Z     logging.warning(">>> Error Connecting:", errc)
[33mservice_main            |[0m 2023-05-29T16:01:55.526058501Z Message: '>>> Error Connecting:'
[33mservice_main            |[0m 2023-05-29T16:01:55.526063631Z Arguments: (ConnectionError(MaxRetryError("HTTPConnectionPool(host='service_author', port=8081): Max retries exceeded with url: /authors/1 (Caused by NewConnectionError('<urllib3.connection.HTTPConnection object at 0x7f6c5a4c36d0>: Failed to establish a new connection: [Errno -2] Name or service not known'))")),)
[33mservice_main            |[0m 2023-05-29T16:01:55.526748610Z INFO:     172.18.0.1:59994 - "GET /presentationsAndAuthor/First%20Presentation HTTP/1.1" 500 Internal Server Error
[33mservice_main            |[0m 2023-05-29T16:01:55.952196933Z WARNING:root:Circuit "test-08" is "Status.CLOSED", failures: 3
[33mservice_main            |[0m 2023-05-29T16:01:55.965104118Z WARNING:root:
[33mservice_main            |[0m 2023-05-29T16:01:56.970111721Z WARNING:root:Circuit "test-08" is "Status.CLOSED", failures: 3
[33mservice_main            |[0m 2023-05-29T16:01:56.986883595Z WARNING:root:
[33mservice_main            |[0m 2023-05-29T16:01:57.415815122Z --- Logging error ---
[33mservice_main            |[0m 2023-05-29T16:01:57.417008821Z Traceback (most recent call last):
[33mservice_main            |[0m 2023-05-29T16:01:57.417450386Z   File "/usr/local/lib/python3.10/dist-packages/urllib3/connection.py", line 174, in _new_conn
[33mservice_main            |[0m 2023-05-29T16:01:57.417505535Z     conn = connection.create_connection(
[33mservice_main            |[0m 2023-05-29T16:01:57.417749073Z   File "/usr/local/lib/python3.10/dist-packages/urllib3/util/connection.py", line 72, in create_connection
[33mservice_main            |[0m 2023-05-29T16:01:57.417773023Z     for res in socket.getaddrinfo(host, port, family, socket.SOCK_STREAM):
[33mservice_main            |[0m 2023-05-29T16:01:57.417995022Z   File "/usr/lib/python3.10/socket.py", line 955, in getaddrinfo
[33mservice_main            |[0m 2023-05-29T16:01:57.418009078Z     for res in _socket.getaddrinfo(host, port, family, type, proto, flags):
[33mservice_main            |[0m 2023-05-29T16:01:57.418484872Z socket.gaierror: [Errno -2] Name or service not known
[33mservice_main            |[0m 2023-05-29T16:01:57.418637395Z 
[33mservice_main            |[0m 2023-05-29T16:01:57.418650520Z During handling of the above exception, another exception occurred:
[33mservice_main            |[0m 2023-05-29T16:01:57.418656753Z 
[33mservice_main            |[0m 2023-05-29T16:01:57.418989787Z Traceback (most recent call last):
[33mservice_main            |[0m 2023-05-29T16:01:57.419299221Z   File "/usr/local/lib/python3.10/dist-packages/urllib3/connectionpool.py", line 703, in urlopen
[33mservice_main            |[0m 2023-05-29T16:01:57.419313484Z     httplib_response = self._make_request(
[33mservice_main            |[0m 2023-05-29T16:01:57.419431387Z   File "/usr/local/lib/python3.10/dist-packages/urllib3/connectionpool.py", line 398, in _make_request
[33mservice_main            |[0m 2023-05-29T16:01:57.419444100Z     conn.request(method, url, **httplib_request_kw)
[33mservice_main            |[0m 2023-05-29T16:01:57.419595912Z   File "/usr/local/lib/python3.10/dist-packages/urllib3/connection.py", line 239, in request
[33mservice_main            |[0m 2023-05-29T16:01:57.419689311Z     super(HTTPConnection, self).request(method, url, body=body, headers=headers)
[33mservice_main            |[0m 2023-05-29T16:01:57.419883878Z   File "/usr/lib/python3.10/http/client.py", line 1282, in request
[33mservice_main            |[0m 2023-05-29T16:01:57.419898608Z     self._send_request(method, url, body, headers, encode_chunked)
[33mservice_main            |[0m 2023-05-29T16:01:57.420466103Z   File "/usr/lib/python3.10/http/client.py", line 1328, in _send_request
[33mservice_main            |[0m 2023-05-29T16:01:57.420484105Z     self.endheaders(body, encode_chunked=encode_chunked)
[33mservice_main            |[0m 2023-05-29T16:01:57.420871033Z   File "/usr/lib/python3.10/http/client.py", line 1277, in endheaders
[33mservice_main            |[0m 2023-05-29T16:01:57.420889714Z     self._send_output(message_body, encode_chunked=encode_chunked)
[33mservice_main            |[0m 2023-05-29T16:01:57.421061304Z   File "/usr/lib/python3.10/http/client.py", line 1037, in _send_output
[33mservice_main            |[0m 2023-05-29T16:01:57.421100835Z     self.send(msg)
[33mservice_main            |[0m 2023-05-29T16:01:57.421475754Z   File "/usr/lib/python3.10/http/client.py", line 975, in send
[33mservice_main            |[0m 2023-05-29T16:01:57.421517264Z     self.connect()
[33mservice_main            |[0m 2023-05-29T16:01:57.421783490Z   File "/usr/local/lib/python3.10/dist-packages/urllib3/connection.py", line 205, in connect
[33mservice_main            |[0m 2023-05-29T16:01:57.421797521Z     conn = self._new_conn()
[33mservice_main            |[0m 2023-05-29T16:01:57.421911808Z   File "/usr/local/lib/python3.10/dist-packages/urllib3/connection.py", line 186, in _new_conn
[33mservice_main            |[0m 2023-05-29T16:01:57.421985525Z     raise NewConnectionError(
[33mservice_main            |[0m 2023-05-29T16:01:57.422224653Z urllib3.exceptions.NewConnectionError: <urllib3.connection.HTTPConnection object at 0x7f6c59a7d870>: Failed to establish a new connection: [Errno -2] Name or service not known
[33mservice_main            |[0m 2023-05-29T16:01:57.422359728Z 
[33mservice_main            |[0m 2023-05-29T16:01:57.422372959Z During handling of the above exception, another exception occurred:
[33mservice_main            |[0m 2023-05-29T16:01:57.422430020Z 
[33mservice_main            |[0m 2023-05-29T16:01:57.422667716Z Traceback (most recent call last):
[33mservice_main            |[0m 2023-05-29T16:01:57.423011517Z   File "/usr/local/lib/python3.10/dist-packages/requests/adapters.py", line 489, in send
[33mservice_main            |[0m 2023-05-29T16:01:57.423060817Z     resp = conn.urlopen(
[33mservice_main            |[0m 2023-05-29T16:01:57.423430529Z   File "/usr/local/lib/python3.10/dist-packages/urllib3/connectionpool.py", line 787, in urlopen
[33mservice_main            |[0m 2023-05-29T16:01:57.423446692Z     retries = retries.increment(
[33mservice_main            |[0m 2023-05-29T16:01:57.423559080Z   File "/usr/local/lib/python3.10/dist-packages/urllib3/util/retry.py", line 592, in increment
[33mservice_main            |[0m 2023-05-29T16:01:57.423572151Z     raise MaxRetryError(_pool, url, error or ResponseError(cause))
[33mservice_main            |[0m 2023-05-29T16:01:57.423836613Z urllib3.exceptions.MaxRetryError: HTTPConnectionPool(host='service_author', port=8081): Max retries exceeded with url: /authors/1 (Caused by NewConnectionError('<urllib3.connection.HTTPConnection object at 0x7f6c59a7d870>: Failed to establish a new connection: [Errno -2] Name or service not known'))
[33mservice_main            |[0m 2023-05-29T16:01:57.424175727Z 
[33mservice_main            |[0m 2023-05-29T16:01:57.424189420Z During handling of the above exception, another exception occurred:
[33mservice_main            |[0m 2023-05-29T16:01:57.424210579Z 
[33mservice_main            |[0m 2023-05-29T16:01:57.424395980Z Traceback (most recent call last):
[33mservice_main            |[0m 2023-05-29T16:01:57.424774275Z   File "/./service_main.py", line 78, in get_author
[33mservice_main            |[0m 2023-05-29T16:01:57.424790498Z     response_author = requests.get("http://" + service_author + "/authors/" + str(id))
[33mservice_main            |[0m 2023-05-29T16:01:57.425084325Z   File "/usr/local/lib/python3.10/dist-packages/requests/api.py", line 73, in get
[33mservice_main            |[0m 2023-05-29T16:01:57.425105611Z     return request("get", url, params=params, **kwargs)
[33mservice_main            |[0m 2023-05-29T16:01:57.425549908Z   File "/usr/local/lib/python3.10/dist-packages/requests/api.py", line 59, in request
[33mservice_main            |[0m 2023-05-29T16:01:57.425565811Z     return session.request(method=method, url=url, **kwargs)
[33mservice_main            |[0m 2023-05-29T16:01:57.425736566Z   File "/usr/local/lib/python3.10/dist-packages/requests/sessions.py", line 587, in request
[33mservice_main            |[0m 2023-05-29T16:01:57.425750119Z     resp = self.send(prep, **send_kwargs)
[33mservice_main            |[0m 2023-05-29T16:01:57.425862573Z   File "/usr/local/lib/python3.10/dist-packages/requests/sessions.py", line 701, in send
[33mservice_main            |[0m 2023-05-29T16:01:57.425875071Z     r = adapter.send(request, **kwargs)
[33mservice_main            |[0m 2023-05-29T16:01:57.426101512Z   File "/usr/local/lib/python3.10/dist-packages/requests/adapters.py", line 565, in send
[33mservice_main            |[0m 2023-05-29T16:01:57.426193994Z     raise ConnectionError(e, request=request)
[33mservice_main            |[0m 2023-05-29T16:01:57.426496884Z requests.exceptions.ConnectionError: HTTPConnectionPool(host='service_author', port=8081): Max retries exceeded with url: /authors/1 (Caused by NewConnectionError('<urllib3.connection.HTTPConnection object at 0x7f6c59a7d870>: Failed to establish a new connection: [Errno -2] Name or service not known'))
[33mservice_main            |[0m 2023-05-29T16:01:57.426843857Z 
[33mservice_main            |[0m 2023-05-29T16:01:57.426862294Z During handling of the above exception, another exception occurred:
[33mservice_main            |[0m 2023-05-29T16:01:57.426869273Z 
[33mservice_main            |[0m 2023-05-29T16:01:57.427128505Z Traceback (most recent call last):
[33mservice_main            |[0m 2023-05-29T16:01:57.427588457Z   File "/usr/lib/python3.10/logging/__init__.py", line 1100, in emit
[33mservice_main            |[0m 2023-05-29T16:01:57.427608883Z     msg = self.format(record)
[33mservice_main            |[0m 2023-05-29T16:01:57.427929562Z   File "/usr/lib/python3.10/logging/__init__.py", line 943, in format
[33mservice_main            |[0m 2023-05-29T16:01:57.427956486Z     return fmt.format(record)
[33mservice_main            |[0m 2023-05-29T16:01:57.428297399Z   File "/usr/lib/python3.10/logging/__init__.py", line 678, in format
[33mservice_main            |[0m 2023-05-29T16:01:57.428316608Z     record.message = record.getMessage()
[33mservice_main            |[0m 2023-05-29T16:01:57.428704782Z   File "/usr/lib/python3.10/logging/__init__.py", line 368, in getMessage
[33mservice_main            |[0m 2023-05-29T16:01:57.428724987Z     msg = msg % self.args
[33mservice_main            |[0m 2023-05-29T16:01:57.428944088Z TypeError: not all arguments converted during string formatting
[33mservice_main            |[0m 2023-05-29T16:01:57.429582957Z Call stack:
[33mservice_main            |[0m 2023-05-29T16:01:57.430877779Z   File "<string>", line 1, in <module>
[33mservice_main            |[0m 2023-05-29T16:01:57.431211022Z   File "/usr/lib/python3.10/multiprocessing/spawn.py", line 116, in spawn_main
[33mservice_main            |[0m 2023-05-29T16:01:57.431293372Z     exitcode = _main(fd, parent_sentinel)
[33mservice_main            |[0m 2023-05-29T16:01:57.431590451Z   File "/usr/lib/python3.10/multiprocessing/spawn.py", line 129, in _main
[33mservice_main            |[0m 2023-05-29T16:01:57.431605561Z     return self._bootstrap(parent_sentinel)
[33mservice_main            |[0m 2023-05-29T16:01:57.431879519Z   File "/usr/lib/python3.10/multiprocessing/process.py", line 314, in _bootstrap
[33mservice_main            |[0m 2023-05-29T16:01:57.431893865Z     self.run()
[33mservice_main            |[0m 2023-05-29T16:01:57.432180430Z   File "/usr/lib/python3.10/multiprocessing/process.py", line 108, in run
[33mservice_main            |[0m 2023-05-29T16:01:57.432194300Z     self._target(*self._args, **self._kwargs)
[33mservice_main            |[0m 2023-05-29T16:01:57.432485577Z   File "/usr/local/lib/python3.10/dist-packages/uvicorn/_subprocess.py", line 76, in subprocess_started
[33mservice_main            |[0m 2023-05-29T16:01:57.432501292Z     target(sockets=sockets)
[33mservice_main            |[0m 2023-05-29T16:01:57.432772072Z   File "/usr/local/lib/python3.10/dist-packages/uvicorn/server.py", line 60, in run
[33mservice_main            |[0m 2023-05-29T16:01:57.432805813Z     return asyncio.run(self.serve(sockets=sockets))
[33mservice_main            |[0m 2023-05-29T16:01:57.433120695Z   File "/usr/lib/python3.10/asyncio/runners.py", line 44, in run
[33mservice_main            |[0m 2023-05-29T16:01:57.433135812Z     return loop.run_until_complete(main)
[33mservice_main            |[0m 2023-05-29T16:01:57.433290322Z   File "/usr/lib/python3.10/asyncio/base_events.py", line 633, in run_until_complete
[33mservice_main            |[0m 2023-05-29T16:01:57.433304726Z     self.run_forever()
[33mservice_main            |[0m 2023-05-29T16:01:57.433580282Z   File "/usr/lib/python3.10/asyncio/base_events.py", line 600, in run_forever
[33mservice_main            |[0m 2023-05-29T16:01:57.433628976Z     self._run_once()
[33mservice_main            |[0m 2023-05-29T16:01:57.433848267Z   File "/usr/lib/python3.10/asyncio/base_events.py", line 1896, in _run_once
[33mservice_main            |[0m 2023-05-29T16:01:57.433861862Z     handle._run()
[33mservice_main            |[0m 2023-05-29T16:01:57.433973753Z   File "/usr/lib/python3.10/asyncio/events.py", line 80, in _run
[33mservice_main            |[0m 2023-05-29T16:01:57.434041510Z     self._context.run(self._callback, *self._args)
[33mservice_main            |[0m 2023-05-29T16:01:57.434239503Z   File "/usr/local/lib/python3.10/dist-packages/uvicorn/protocols/http/httptools_impl.py", line 419, in run_asgi
[33mservice_main            |[0m 2023-05-29T16:01:57.434272083Z     result = await app(  # type: ignore[func-returns-value]
[33mservice_main            |[0m 2023-05-29T16:01:57.434437284Z   File "/usr/local/lib/python3.10/dist-packages/uvicorn/middleware/proxy_headers.py", line 78, in __call__
[33mservice_main            |[0m 2023-05-29T16:01:57.434451126Z     return await self.app(scope, receive, send)
[33mservice_main            |[0m 2023-05-29T16:01:57.434744114Z   File "/usr/local/lib/python3.10/dist-packages/fastapi/applications.py", line 271, in __call__
[33mservice_main            |[0m 2023-05-29T16:01:57.434760454Z     await super().__call__(scope, receive, send)
[33mservice_main            |[0m 2023-05-29T16:01:57.435078555Z   File "/usr/local/lib/python3.10/dist-packages/starlette/applications.py", line 118, in __call__
[33mservice_main            |[0m 2023-05-29T16:01:57.435092963Z     await self.middleware_stack(scope, receive, send)
[33mservice_main            |[0m 2023-05-29T16:01:57.435219570Z   File "/usr/local/lib/python3.10/dist-packages/starlette/middleware/errors.py", line 162, in __call__
[33mservice_main            |[0m 2023-05-29T16:01:57.435249097Z     await self.app(scope, receive, _send)
[33mservice_main            |[0m 2023-05-29T16:01:57.435531451Z   File "/usr/local/lib/python3.10/dist-packages/starlette/middleware/exceptions.py", line 68, in __call__
[33mservice_main            |[0m 2023-05-29T16:01:57.435554934Z     await self.app(scope, receive, sender)
[33mservice_main            |[0m 2023-05-29T16:01:57.438032158Z   File "/usr/local/lib/python3.10/dist-packages/fastapi/middleware/asyncexitstack.py", line 18, in __call__
[33mservice_main            |[0m 2023-05-29T16:01:57.438075619Z     await self.app(scope, receive, send)
[33mservice_main            |[0m 2023-05-29T16:01:57.438083054Z   File "/usr/local/lib/python3.10/dist-packages/starlette/routing.py", line 706, in __call__
[33mservice_main            |[0m 2023-05-29T16:01:57.438087728Z     await route.handle(scope, receive, send)
[33mservice_main            |[0m 2023-05-29T16:01:57.438092316Z   File "/usr/local/lib/python3.10/dist-packages/starlette/routing.py", line 276, in handle
[33mservice_main            |[0m 2023-05-29T16:01:57.438096833Z     await self.app(scope, receive, send)
[33mservice_main            |[0m 2023-05-29T16:01:57.438101110Z   File "/usr/local/lib/python3.10/dist-packages/starlette/routing.py", line 66, in app
[33mservice_main            |[0m 2023-05-29T16:01:57.438105826Z     response = await func(request)
[33mservice_main            |[0m 2023-05-29T16:01:57.438110225Z   File "/usr/local/lib/python3.10/dist-packages/fastapi/routing.py", line 237, in app
[33mservice_main            |[0m 2023-05-29T16:01:57.438114880Z     raw_response = await run_endpoint_function(
[33mservice_main            |[0m 2023-05-29T16:01:57.438119444Z   File "/usr/local/lib/python3.10/dist-packages/fastapi/routing.py", line 163, in run_endpoint_function
[33mservice_main            |[0m 2023-05-29T16:01:57.438124114Z     return await dependant.call(**values)
[33mservice_main            |[0m 2023-05-29T16:01:57.438128062Z   File "/./service_main.py", line 110, in read_presentation
[33mservice_main            |[0m 2023-05-29T16:01:57.438132476Z     author = get_author(presentation.author_id)
[33mservice_main            |[0m 2023-05-29T16:01:57.438136656Z   File "/./cbhomemade.py", line 39, in wrapper
[33mservice_main            |[0m 2023-05-29T16:01:57.438140977Z     result = self.func(*args, **kwargs)
[33mservice_main            |[0m 2023-05-29T16:01:57.438145084Z   File "/./service_main.py", line 80, in get_author
[33mservice_main            |[0m 2023-05-29T16:01:57.438149281Z     logging.warning(">>> Error Connecting:", errc)
[33mservice_main            |[0m 2023-05-29T16:01:57.438154031Z Message: '>>> Error Connecting:'
[33mservice_main            |[0m 2023-05-29T16:01:57.438158294Z Arguments: (ConnectionError(MaxRetryError("HTTPConnectionPool(host='service_author', port=8081): Max retries exceeded with url: /authors/1 (Caused by NewConnectionError('<urllib3.connection.HTTPConnection object at 0x7f6c59a7d870>: Failed to establish a new connection: [Errno -2] Name or service not known'))")),)
[33mservice_main            |[0m 2023-05-29T16:01:57.438328037Z INFO:     172.18.0.1:60000 - "GET /presentationsAndAuthor/First%20Presentation HTTP/1.1" 500 Internal Server Error
[33mservice_main            |[0m 2023-05-29T16:01:57.990374042Z WARNING:root:Circuit "test-08" is "Status.CLOSED", failures: 4
[33mservice_main            |[0m 2023-05-29T16:01:58.004307870Z WARNING:root:
[33mservice_main            |[0m 2023-05-29T16:01:59.013643816Z WARNING:root:Circuit "test-08" is "Status.CLOSED", failures: 4
[33mservice_main            |[0m 2023-05-29T16:01:59.032375518Z WARNING:root:
[33mservice_main            |[0m 2023-05-29T16:01:59.119689430Z --- Logging error ---
[33mservice_main            |[0m 2023-05-29T16:01:59.121626559Z Traceback (most recent call last):
[33mservice_main            |[0m 2023-05-29T16:01:59.121915023Z   File "/usr/local/lib/python3.10/dist-packages/urllib3/connection.py", line 174, in _new_conn
[33mservice_main            |[0m 2023-05-29T16:01:59.121942782Z     conn = connection.create_connection(
[33mservice_main            |[0m 2023-05-29T16:01:59.122445563Z   File "/usr/local/lib/python3.10/dist-packages/urllib3/util/connection.py", line 72, in create_connection
[33mservice_main            |[0m 2023-05-29T16:01:59.122464847Z     for res in socket.getaddrinfo(host, port, family, socket.SOCK_STREAM):
[33mservice_main            |[0m 2023-05-29T16:01:59.123592967Z   File "/usr/lib/python3.10/socket.py", line 955, in getaddrinfo
[33mservice_main            |[0m 2023-05-29T16:01:59.123675467Z     for res in _socket.getaddrinfo(host, port, family, type, proto, flags):
[33mservice_main            |[0m 2023-05-29T16:01:59.123895819Z socket.gaierror: [Errno -2] Name or service not known
[33mservice_main            |[0m 2023-05-29T16:01:59.125007440Z 
[33mservice_main            |[0m 2023-05-29T16:01:59.125027241Z During handling of the above exception, another exception occurred:
[33mservice_main            |[0m 2023-05-29T16:01:59.125031130Z 
[33mservice_main            |[0m 2023-05-29T16:01:59.125192209Z Traceback (most recent call last):
[33mservice_main            |[0m 2023-05-29T16:01:59.126119176Z   File "/usr/local/lib/python3.10/dist-packages/urllib3/connectionpool.py", line 703, in urlopen
[33mservice_main            |[0m 2023-05-29T16:01:59.126193754Z     httplib_response = self._make_request(
[33mservice_main            |[0m 2023-05-29T16:01:59.126759401Z   File "/usr/local/lib/python3.10/dist-packages/urllib3/connectionpool.py", line 398, in _make_request
[33mservice_main            |[0m 2023-05-29T16:01:59.126792604Z     conn.request(method, url, **httplib_request_kw)
[33mservice_main            |[0m 2023-05-29T16:01:59.127611681Z   File "/usr/local/lib/python3.10/dist-packages/urllib3/connection.py", line 239, in request
[33mservice_main            |[0m 2023-05-29T16:01:59.127752029Z     super(HTTPConnection, self).request(method, url, body=body, headers=headers)
[33mservice_main            |[0m 2023-05-29T16:01:59.128183228Z   File "/usr/lib/python3.10/http/client.py", line 1282, in request
[33mservice_main            |[0m 2023-05-29T16:01:59.128199411Z     self._send_request(method, url, body, headers, encode_chunked)
[33mservice_main            |[0m 2023-05-29T16:01:59.129093743Z   File "/usr/lib/python3.10/http/client.py", line 1328, in _send_request
[33mservice_main            |[0m 2023-05-29T16:01:59.129116308Z     self.endheaders(body, encode_chunked=encode_chunked)
[33mservice_main            |[0m 2023-05-29T16:01:59.129122875Z   File "/usr/lib/python3.10/http/client.py", line 1277, in endheaders
[33mservice_main            |[0m 2023-05-29T16:01:59.129143104Z     self._send_output(message_body, encode_chunked=encode_chunked)
[33mservice_main            |[0m 2023-05-29T16:01:59.129157902Z   File "/usr/lib/python3.10/http/client.py", line 1037, in _send_output
[33mservice_main            |[0m 2023-05-29T16:01:59.129170223Z     self.send(msg)
[33mservice_main            |[0m 2023-05-29T16:01:59.129176433Z   File "/usr/lib/python3.10/http/client.py", line 975, in send
[33mservice_main            |[0m 2023-05-29T16:01:59.129182128Z     self.connect()
[33mservice_main            |[0m 2023-05-29T16:01:59.129187272Z   File "/usr/local/lib/python3.10/dist-packages/urllib3/connection.py", line 205, in connect
[33mservice_main            |[0m 2023-05-29T16:01:59.129192723Z     conn = self._new_conn()
[33mservice_main            |[0m 2023-05-29T16:01:59.129197845Z   File "/usr/local/lib/python3.10/dist-packages/urllib3/connection.py", line 186, in _new_conn
[33mservice_main            |[0m 2023-05-29T16:01:59.129205762Z     raise NewConnectionError(
[33mservice_main            |[0m 2023-05-29T16:01:59.129226950Z urllib3.exceptions.NewConnectionError: <urllib3.connection.HTTPConnection object at 0x7f6c59a7e740>: Failed to establish a new connection: [Errno -2] Name or service not known
[33mservice_main            |[0m 2023-05-29T16:01:59.129288725Z 
[33mservice_main            |[0m 2023-05-29T16:01:59.129303885Z During handling of the above exception, another exception occurred:
[33mservice_main            |[0m 2023-05-29T16:01:59.129310632Z 
[33mservice_main            |[0m 2023-05-29T16:01:59.129315999Z Traceback (most recent call last):
[33mservice_main            |[0m 2023-05-29T16:01:59.129961824Z   File "/usr/local/lib/python3.10/dist-packages/requests/adapters.py", line 489, in send
[33mservice_main            |[0m 2023-05-29T16:01:59.129978093Z     resp = conn.urlopen(
[33mservice_main            |[0m 2023-05-29T16:01:59.129984317Z   File "/usr/local/lib/python3.10/dist-packages/urllib3/connectionpool.py", line 787, in urlopen
[33mservice_main            |[0m 2023-05-29T16:01:59.129989940Z     retries = retries.increment(
[33mservice_main            |[0m 2023-05-29T16:01:59.129995108Z   File "/usr/local/lib/python3.10/dist-packages/urllib3/util/retry.py", line 592, in increment
[33mservice_main            |[0m 2023-05-29T16:01:59.130038798Z     raise MaxRetryError(_pool, url, error or ResponseError(cause))
[33mservice_main            |[0m 2023-05-29T16:01:59.130053866Z urllib3.exceptions.MaxRetryError: HTTPConnectionPool(host='service_author', port=8081): Max retries exceeded with url: /authors/1 (Caused by NewConnectionError('<urllib3.connection.HTTPConnection object at 0x7f6c59a7e740>: Failed to establish a new connection: [Errno -2] Name or service not known'))
[33mservice_main            |[0m 2023-05-29T16:01:59.130089839Z 
[33mservice_main            |[0m 2023-05-29T16:01:59.130098369Z During handling of the above exception, another exception occurred:
[33mservice_main            |[0m 2023-05-29T16:01:59.130104108Z 
[33mservice_main            |[0m 2023-05-29T16:01:59.130109227Z Traceback (most recent call last):
[33mservice_main            |[0m 2023-05-29T16:01:59.131679244Z   File "/./service_main.py", line 78, in get_author
[33mservice_main            |[0m 2023-05-29T16:01:59.131708546Z     response_author = requests.get("http://" + service_author + "/authors/" + str(id))
[33mservice_main            |[0m 2023-05-29T16:01:59.131961424Z   File "/usr/local/lib/python3.10/dist-packages/requests/api.py", line 73, in get
[33mservice_main            |[0m 2023-05-29T16:01:59.131977451Z     return request("get", url, params=params, **kwargs)
[33mservice_main            |[0m 2023-05-29T16:01:59.133006555Z   File "/usr/local/lib/python3.10/dist-packages/requests/api.py", line 59, in request
[33mservice_main            |[0m 2023-05-29T16:01:59.133081056Z     return session.request(method=method, url=url, **kwargs)
[33mservice_main            |[0m 2023-05-29T16:01:59.133375600Z   File "/usr/local/lib/python3.10/dist-packages/requests/sessions.py", line 587, in request
[33mservice_main            |[0m 2023-05-29T16:01:59.133677845Z     resp = self.send(prep, **send_kwargs)
[33mservice_main            |[0m 2023-05-29T16:01:59.133684674Z   File "/usr/local/lib/python3.10/dist-packages/requests/sessions.py", line 701, in send
[33mservice_main            |[0m 2023-05-29T16:01:59.133690281Z     r = adapter.send(request, **kwargs)
[33mservice_main            |[0m 2023-05-29T16:01:59.133695154Z   File "/usr/local/lib/python3.10/dist-packages/requests/adapters.py", line 565, in send
[33mservice_main            |[0m 2023-05-29T16:01:59.133700219Z     raise ConnectionError(e, request=request)
[33mservice_main            |[0m 2023-05-29T16:01:59.133704680Z requests.exceptions.ConnectionError: HTTPConnectionPool(host='service_author', port=8081): Max retries exceeded with url: /authors/1 (Caused by NewConnectionError('<urllib3.connection.HTTPConnection object at 0x7f6c59a7e740>: Failed to establish a new connection: [Errno -2] Name or service not known'))
[33mservice_main            |[0m 2023-05-29T16:01:59.133748527Z 
[33mservice_main            |[0m 2023-05-29T16:01:59.133757125Z During handling of the above exception, another exception occurred:
[33mservice_main            |[0m 2023-05-29T16:01:59.133762186Z 
[33mservice_main            |[0m 2023-05-29T16:01:59.133766780Z Traceback (most recent call last):
[33mservice_main            |[0m 2023-05-29T16:01:59.134588479Z   File "/usr/lib/python3.10/logging/__init__.py", line 1100, in emit
[33mservice_main            |[0m 2023-05-29T16:01:59.134644764Z     msg = self.format(record)
[33mservice_main            |[0m 2023-05-29T16:01:59.134961647Z   File "/usr/lib/python3.10/logging/__init__.py", line 943, in format
[33mservice_main            |[0m 2023-05-29T16:01:59.135099999Z     return fmt.format(record)
[33mservice_main            |[0m 2023-05-29T16:01:59.135110209Z   File "/usr/lib/python3.10/logging/__init__.py", line 678, in format
[33mservice_main            |[0m 2023-05-29T16:01:59.135116110Z     record.message = record.getMessage()
[33mservice_main            |[0m 2023-05-29T16:01:59.135540892Z   File "/usr/lib/python3.10/logging/__init__.py", line 368, in getMessage
[33mservice_main            |[0m 2023-05-29T16:01:59.135558083Z     msg = msg % self.args
[33mservice_main            |[0m 2023-05-29T16:01:59.135563336Z TypeError: not all arguments converted during string formatting
[33mservice_main            |[0m 2023-05-29T16:01:59.135719748Z Call stack:
[33mservice_main            |[0m 2023-05-29T16:01:59.141224424Z   File "<string>", line 1, in <module>
[33mservice_main            |[0m 2023-05-29T16:01:59.141529241Z   File "/usr/lib/python3.10/multiprocessing/spawn.py", line 116, in spawn_main
[33mservice_main            |[0m 2023-05-29T16:01:59.141542360Z     exitcode = _main(fd, parent_sentinel)
[33mservice_main            |[0m 2023-05-29T16:01:59.141946206Z   File "/usr/lib/python3.10/multiprocessing/spawn.py", line 129, in _main
[33mservice_main            |[0m 2023-05-29T16:01:59.142118409Z     return self._bootstrap(parent_sentinel)
[33mservice_main            |[0m 2023-05-29T16:01:59.142391575Z   File "/usr/lib/python3.10/multiprocessing/process.py", line 314, in _bootstrap
[33mservice_main            |[0m 2023-05-29T16:01:59.142444985Z     self.run()
[33mservice_main            |[0m 2023-05-29T16:01:59.143223338Z   File "/usr/lib/python3.10/multiprocessing/process.py", line 108, in run
[33mservice_main            |[0m 2023-05-29T16:01:59.143898743Z     self._target(*self._args, **self._kwargs)
[33mservice_main            |[0m 2023-05-29T16:01:59.147094943Z   File "/usr/local/lib/python3.10/dist-packages/uvicorn/_subprocess.py", line 76, in subprocess_started
[33mservice_main            |[0m 2023-05-29T16:01:59.147134310Z     target(sockets=sockets)
[33mservice_main            |[0m 2023-05-29T16:01:59.148474001Z   File "/usr/local/lib/python3.10/dist-packages/uvicorn/server.py", line 60, in run
[33mservice_main            |[0m 2023-05-29T16:01:59.148498287Z     return asyncio.run(self.serve(sockets=sockets))
[33mservice_main            |[0m 2023-05-29T16:01:59.148505689Z   File "/usr/lib/python3.10/asyncio/runners.py", line 44, in run
[33mservice_main            |[0m 2023-05-29T16:01:59.148511289Z     return loop.run_until_complete(main)
[33mservice_main            |[0m 2023-05-29T16:01:59.148516466Z   File "/usr/lib/python3.10/asyncio/base_events.py", line 633, in run_until_complete
[33mservice_main            |[0m 2023-05-29T16:01:59.148522257Z     self.run_forever()
[33mservice_main            |[0m 2023-05-29T16:01:59.148527560Z   File "/usr/lib/python3.10/asyncio/base_events.py", line 600, in run_forever
[33mservice_main            |[0m 2023-05-29T16:01:59.148551683Z     self._run_once()
[33mservice_main            |[0m 2023-05-29T16:01:59.148558727Z   File "/usr/lib/python3.10/asyncio/base_events.py", line 1896, in _run_once
[33mservice_main            |[0m 2023-05-29T16:01:59.148564629Z     handle._run()
[33mservice_main            |[0m 2023-05-29T16:01:59.148570149Z   File "/usr/lib/python3.10/asyncio/events.py", line 80, in _run
[33mservice_main            |[0m 2023-05-29T16:01:59.148576865Z     self._context.run(self._callback, *self._args)
[33mservice_main            |[0m 2023-05-29T16:01:59.148582364Z   File "/usr/local/lib/python3.10/dist-packages/uvicorn/protocols/http/httptools_impl.py", line 419, in run_asgi
[33mservice_main            |[0m 2023-05-29T16:01:59.148588093Z     result = await app(  # type: ignore[func-returns-value]
[33mservice_main            |[0m 2023-05-29T16:01:59.148593267Z   File "/usr/local/lib/python3.10/dist-packages/uvicorn/middleware/proxy_headers.py", line 78, in __call__
[33mservice_main            |[0m 2023-05-29T16:01:59.148599013Z     return await self.app(scope, receive, send)
[33mservice_main            |[0m 2023-05-29T16:01:59.148604386Z   File "/usr/local/lib/python3.10/dist-packages/fastapi/applications.py", line 271, in __call__
[33mservice_main            |[0m 2023-05-29T16:01:59.148609724Z     await super().__call__(scope, receive, send)
[33mservice_main            |[0m 2023-05-29T16:01:59.148614732Z   File "/usr/local/lib/python3.10/dist-packages/starlette/applications.py", line 118, in __call__
[33mservice_main            |[0m 2023-05-29T16:01:59.148619965Z     await self.middleware_stack(scope, receive, send)
[33mservice_main            |[0m 2023-05-29T16:01:59.148625578Z   File "/usr/local/lib/python3.10/dist-packages/starlette/middleware/errors.py", line 162, in __call__
[33mservice_main            |[0m 2023-05-29T16:01:59.148631173Z     await self.app(scope, receive, _send)
[33mservice_main            |[0m 2023-05-29T16:01:59.148636533Z   File "/usr/local/lib/python3.10/dist-packages/starlette/middleware/exceptions.py", line 68, in __call__
[33mservice_main            |[0m 2023-05-29T16:01:59.148641915Z     await self.app(scope, receive, sender)
[33mservice_main            |[0m 2023-05-29T16:01:59.148646987Z   File "/usr/local/lib/python3.10/dist-packages/fastapi/middleware/asyncexitstack.py", line 18, in __call__
[33mservice_main            |[0m 2023-05-29T16:01:59.148652917Z     await self.app(scope, receive, send)
[33mservice_main            |[0m 2023-05-29T16:01:59.148660451Z   File "/usr/local/lib/python3.10/dist-packages/starlette/routing.py", line 706, in __call__
[33mservice_main            |[0m 2023-05-29T16:01:59.148666584Z     await route.handle(scope, receive, send)
[33mservice_main            |[0m 2023-05-29T16:01:59.148671888Z   File "/usr/local/lib/python3.10/dist-packages/starlette/routing.py", line 276, in handle
[33mservice_main            |[0m 2023-05-29T16:01:59.148677382Z     await self.app(scope, receive, send)
[33mservice_main            |[0m 2023-05-29T16:01:59.148683644Z   File "/usr/local/lib/python3.10/dist-packages/starlette/routing.py", line 66, in app
[33mservice_main            |[0m 2023-05-29T16:01:59.148689468Z     response = await func(request)
[33mservice_main            |[0m 2023-05-29T16:01:59.148694397Z   File "/usr/local/lib/python3.10/dist-packages/fastapi/routing.py", line 237, in app
[33mservice_main            |[0m 2023-05-29T16:01:59.148699569Z     raw_response = await run_endpoint_function(
[33mservice_main            |[0m 2023-05-29T16:01:59.148704226Z   File "/usr/local/lib/python3.10/dist-packages/fastapi/routing.py", line 163, in run_endpoint_function
[33mservice_main            |[0m 2023-05-29T16:01:59.148709507Z     return await dependant.call(**values)
[33mservice_main            |[0m 2023-05-29T16:01:59.148723614Z   File "/./service_main.py", line 110, in read_presentation
[33mservice_main            |[0m 2023-05-29T16:01:59.148729961Z     author = get_author(presentation.author_id)
[33mservice_main            |[0m 2023-05-29T16:01:59.148735144Z   File "/./cbhomemade.py", line 39, in wrapper
[33mservice_main            |[0m 2023-05-29T16:01:59.148740132Z     result = self.func(*args, **kwargs)
[33mservice_main            |[0m 2023-05-29T16:01:59.148744963Z   File "/./service_main.py", line 80, in get_author
[33mservice_main            |[0m 2023-05-29T16:01:59.148749802Z     logging.warning(">>> Error Connecting:", errc)
[33mservice_main            |[0m 2023-05-29T16:01:59.148755450Z Message: '>>> Error Connecting:'
[33mservice_main            |[0m 2023-05-29T16:01:59.148760735Z Arguments: (ConnectionError(MaxRetryError("HTTPConnectionPool(host='service_author', port=8081): Max retries exceeded with url: /authors/1 (Caused by NewConnectionError('<urllib3.connection.HTTPConnection object at 0x7f6c59a7e740>: Failed to establish a new connection: [Errno -2] Name or service not known'))")),)
[33mservice_main            |[0m 2023-05-29T16:01:59.148793790Z Failed attempt count: 5
[33mservice_main            |[0m 2023-05-29T16:01:59.148800757Z Switching to OPEN
[33mservice_main            |[0m 2023-05-29T16:01:59.148805822Z INFO:     172.18.0.1:60006 - "GET /presentationsAndAuthor/First%20Presentation HTTP/1.1" 500 Internal Server Error
[33mservice_main            |[0m 2023-05-29T16:02:00.015904701Z WARNING:root:Circuit "test-08" is "Status.OPEN", failures: 5
[33mservice_main            |[0m 2023-05-29T16:02:00.058701659Z WARNING:root:
[33mservice_main            |[0m 2023-05-29T16:02:00.060413287Z CRITICAL:root:Circuit OPEN
[33mservice_main            |[0m 2023-05-29T16:02:00.060953632Z INFO:     172.18.0.1:60012 - "GET /presentationsAndAuthor/First%20Presentation HTTP/1.1" 200 OK
[33mservice_main            |[0m 2023-05-29T16:02:01.063650323Z WARNING:root:Circuit "test-08" is "Status.OPEN", failures: 5
[33mservice_main            |[0m 2023-05-29T16:02:01.094096209Z WARNING:root:
[33mservice_main            |[0m 2023-05-29T16:02:01.152846238Z CRITICAL:root:Circuit OPEN
[33mservice_main            |[0m 2023-05-29T16:02:01.154100960Z INFO:     172.18.0.1:60018 - "GET /presentationsAndAuthor/First%20Presentation HTTP/1.1" 200 OK
[33mservice_main            |[0m 2023-05-29T16:02:02.097158469Z WARNING:root:Circuit "test-08" is "Status.OPEN", failures: 5
[33mservice_main            |[0m 2023-05-29T16:02:02.123549794Z WARNING:root:
[33mservice_main            |[0m 2023-05-29T16:02:03.000710345Z CRITICAL:root:Circuit OPEN
[33mservice_main            |[0m 2023-05-29T16:02:03.001528266Z INFO:     172.18.0.1:60024 - "GET /presentationsAndAuthor/First%20Presentation HTTP/1.1" 200 OK
[33mservice_main            |[0m 2023-05-29T16:02:03.126891571Z WARNING:root:Circuit "test-08" is "Status.OPEN", failures: 5
[33mservice_main            |[0m 2023-05-29T16:02:03.142848041Z WARNING:root:
[33mservice_main            |[0m 2023-05-29T16:02:04.146925358Z WARNING:root:Circuit "test-08" is "Status.OPEN", failures: 5
[33mservice_main            |[0m 2023-05-29T16:02:04.162779027Z WARNING:root:
[33mservice_main            |[0m 2023-05-29T16:02:05.167054152Z WARNING:root:Circuit "test-08" is "Status.OPEN", failures: 5
[33mservice_main            |[0m 2023-05-29T16:02:05.190092846Z WARNING:root:
[33mservice_main            |[0m 2023-05-29T16:02:05.547173181Z CRITICAL:root:Circuit OPEN
[33mservice_main            |[0m 2023-05-29T16:02:05.548216152Z INFO:     172.18.0.1:60030 - "GET /presentationsAndAuthor/First%20Presentation HTTP/1.1" 200 OK
[33mservice_main            |[0m 2023-05-29T16:02:06.194172017Z WARNING:root:Circuit "test-08" is "Status.OPEN", failures: 5
[33mservice_main            |[0m 2023-05-29T16:02:06.210069652Z WARNING:root:
[33mservice_main            |[0m 2023-05-29T16:02:07.213826639Z WARNING:root:Circuit "test-08" is "Status.OPEN", failures: 5
[33mservice_main            |[0m 2023-05-29T16:02:07.232043331Z WARNING:root:
[33mservice_main            |[0m 2023-05-29T16:02:07.580661515Z CRITICAL:root:Circuit OPEN
[33mservice_main            |[0m 2023-05-29T16:02:07.581783555Z INFO:     172.18.0.1:60036 - "GET /presentationsAndAuthor/First%20Presentation HTTP/1.1" 200 OK
[33mservice_main            |[0m 2023-05-29T16:02:08.236073983Z WARNING:root:Circuit "test-08" is "Status.OPEN", failures: 5
[33mservice_main            |[0m 2023-05-29T16:02:08.250278418Z WARNING:root:
[33mservice_main            |[0m 2023-05-29T16:02:09.261092462Z WARNING:root:Circuit "test-08" is "Status.HALF_OPEN", failures: 5
[33mservice_main            |[0m 2023-05-29T16:02:09.277100589Z WARNING:root:
[33mservice_main            |[0m 2023-05-29T16:02:09.516585246Z --- Logging error ---
[33mservice_main            |[0m 2023-05-29T16:02:09.517883773Z Traceback (most recent call last):
[33mservice_main            |[0m 2023-05-29T16:02:09.518454882Z   File "/usr/local/lib/python3.10/dist-packages/urllib3/connection.py", line 174, in _new_conn
[33mservice_main            |[0m 2023-05-29T16:02:09.518474252Z     conn = connection.create_connection(
[33mservice_main            |[0m 2023-05-29T16:02:09.518979729Z   File "/usr/local/lib/python3.10/dist-packages/urllib3/util/connection.py", line 72, in create_connection
[33mservice_main            |[0m 2023-05-29T16:02:09.519115252Z     for res in socket.getaddrinfo(host, port, family, socket.SOCK_STREAM):
[33mservice_main            |[0m 2023-05-29T16:02:09.519809659Z   File "/usr/lib/python3.10/socket.py", line 955, in getaddrinfo
[33mservice_main            |[0m 2023-05-29T16:02:09.519831987Z     for res in _socket.getaddrinfo(host, port, family, type, proto, flags):
[33mservice_main            |[0m 2023-05-29T16:02:09.520374534Z socket.gaierror: [Errno -2] Name or service not known
[33mservice_main            |[0m 2023-05-29T16:02:09.520898326Z 
[33mservice_main            |[0m 2023-05-29T16:02:09.520915808Z During handling of the above exception, another exception occurred:
[33mservice_main            |[0m 2023-05-29T16:02:09.520921865Z 
[33mservice_main            |[0m 2023-05-29T16:02:09.521353093Z Traceback (most recent call last):
[33mservice_main            |[0m 2023-05-29T16:02:09.522090158Z   File "/usr/local/lib/python3.10/dist-packages/urllib3/connectionpool.py", line 703, in urlopen
[33mservice_main            |[0m 2023-05-29T16:02:09.522110971Z     httplib_response = self._make_request(
[33mservice_main            |[0m 2023-05-29T16:02:09.522560078Z   File "/usr/local/lib/python3.10/dist-packages/urllib3/connectionpool.py", line 398, in _make_request
[33mservice_main            |[0m 2023-05-29T16:02:09.522584910Z     conn.request(method, url, **httplib_request_kw)
[33mservice_main            |[0m 2023-05-29T16:02:09.523267385Z   File "/usr/local/lib/python3.10/dist-packages/urllib3/connection.py", line 239, in request
[33mservice_main            |[0m 2023-05-29T16:02:09.523411587Z     super(HTTPConnection, self).request(method, url, body=body, headers=headers)
[33mservice_main            |[0m 2023-05-29T16:02:09.523812293Z   File "/usr/lib/python3.10/http/client.py", line 1282, in request
[33mservice_main            |[0m 2023-05-29T16:02:09.523900678Z     self._send_request(method, url, body, headers, encode_chunked)
[33mservice_main            |[0m 2023-05-29T16:02:09.524316591Z   File "/usr/lib/python3.10/http/client.py", line 1328, in _send_request
[33mservice_main            |[0m 2023-05-29T16:02:09.524336108Z     self.endheaders(body, encode_chunked=encode_chunked)
[33mservice_main            |[0m 2023-05-29T16:02:09.524925127Z   File "/usr/lib/python3.10/http/client.py", line 1277, in endheaders
[33mservice_main            |[0m 2023-05-29T16:02:09.524945653Z     self._send_output(message_body, encode_chunked=encode_chunked)
[33mservice_main            |[0m 2023-05-29T16:02:09.525720963Z   File "/usr/lib/python3.10/http/client.py", line 1037, in _send_output
[33mservice_main            |[0m 2023-05-29T16:02:09.525742622Z     self.send(msg)
[33mservice_main            |[0m 2023-05-29T16:02:09.526274426Z   File "/usr/lib/python3.10/http/client.py", line 975, in send
[33mservice_main            |[0m 2023-05-29T16:02:09.526291879Z     self.connect()
[33mservice_main            |[0m 2023-05-29T16:02:09.526999282Z   File "/usr/local/lib/python3.10/dist-packages/urllib3/connection.py", line 205, in connect
[33mservice_main            |[0m 2023-05-29T16:02:09.527021358Z     conn = self._new_conn()
[33mservice_main            |[0m 2023-05-29T16:02:09.527652143Z   File "/usr/local/lib/python3.10/dist-packages/urllib3/connection.py", line 186, in _new_conn
[33mservice_main            |[0m 2023-05-29T16:02:09.527776845Z     raise NewConnectionError(
[33mservice_main            |[0m 2023-05-29T16:02:09.528348270Z urllib3.exceptions.NewConnectionError: <urllib3.connection.HTTPConnection object at 0x7f6c59a7d570>: Failed to establish a new connection: [Errno -2] Name or service not known
[33mservice_main            |[0m 2023-05-29T16:02:09.528797262Z 
[33mservice_main            |[0m 2023-05-29T16:02:09.528815778Z During handling of the above exception, another exception occurred:
[33mservice_main            |[0m 2023-05-29T16:02:09.528822953Z 
[33mservice_main            |[0m 2023-05-29T16:02:09.529445187Z Traceback (most recent call last):
[33mservice_main            |[0m 2023-05-29T16:02:09.530247092Z   File "/usr/local/lib/python3.10/dist-packages/requests/adapters.py", line 489, in send
[33mservice_main            |[0m 2023-05-29T16:02:09.530314678Z     resp = conn.urlopen(
[33mservice_main            |[0m 2023-05-29T16:02:09.530714822Z   File "/usr/local/lib/python3.10/dist-packages/urllib3/connectionpool.py", line 787, in urlopen
[33mservice_main            |[0m 2023-05-29T16:02:09.530733189Z     retries = retries.increment(
[33mservice_main            |[0m 2023-05-29T16:02:09.531315158Z   File "/usr/local/lib/python3.10/dist-packages/urllib3/util/retry.py", line 592, in increment
[33mservice_main            |[0m 2023-05-29T16:02:09.531335872Z     raise MaxRetryError(_pool, url, error or ResponseError(cause))
[33mservice_main            |[0m 2023-05-29T16:02:09.531791347Z urllib3.exceptions.MaxRetryError: HTTPConnectionPool(host='service_author', port=8081): Max retries exceeded with url: /authors/1 (Caused by NewConnectionError('<urllib3.connection.HTTPConnection object at 0x7f6c59a7d570>: Failed to establish a new connection: [Errno -2] Name or service not known'))
[33mservice_main            |[0m 2023-05-29T16:02:09.532652144Z 
[33mservice_main            |[0m 2023-05-29T16:02:09.532677557Z During handling of the above exception, another exception occurred:
[33mservice_main            |[0m 2023-05-29T16:02:09.532754792Z 
[33mservice_main            |[0m 2023-05-29T16:02:09.533196696Z Traceback (most recent call last):
[33mservice_main            |[0m 2023-05-29T16:02:09.533897723Z   File "/./service_main.py", line 78, in get_author
[33mservice_main            |[0m 2023-05-29T16:02:09.534032467Z     response_author = requests.get("http://" + service_author + "/authors/" + str(id))
[33mservice_main            |[0m 2023-05-29T16:02:09.534593191Z   File "/usr/local/lib/python3.10/dist-packages/requests/api.py", line 73, in get
[33mservice_main            |[0m 2023-05-29T16:02:09.534611712Z     return request("get", url, params=params, **kwargs)
[33mservice_main            |[0m 2023-05-29T16:02:09.541337062Z   File "/usr/local/lib/python3.10/dist-packages/requests/api.py", line 59, in request
[33mservice_main            |[0m 2023-05-29T16:02:09.541450896Z     return session.request(method=method, url=url, **kwargs)
[33mservice_main            |[0m 2023-05-29T16:02:09.542498121Z   File "/usr/local/lib/python3.10/dist-packages/requests/sessions.py", line 587, in request
[33mservice_main            |[0m 2023-05-29T16:02:09.542630562Z     resp = self.send(prep, **send_kwargs)
[33mservice_main            |[0m 2023-05-29T16:02:09.543501655Z   File "/usr/local/lib/python3.10/dist-packages/requests/sessions.py", line 701, in send
[33mservice_main            |[0m 2023-05-29T16:02:09.543532913Z     r = adapter.send(request, **kwargs)
[33mservice_main            |[0m 2023-05-29T16:02:09.544534282Z   File "/usr/local/lib/python3.10/dist-packages/requests/adapters.py", line 565, in send
[33mservice_main            |[0m 2023-05-29T16:02:09.544643147Z     raise ConnectionError(e, request=request)
[33mservice_main            |[0m 2023-05-29T16:02:09.545426558Z requests.exceptions.ConnectionError: HTTPConnectionPool(host='service_author', port=8081): Max retries exceeded with url: /authors/1 (Caused by NewConnectionError('<urllib3.connection.HTTPConnection object at 0x7f6c59a7d570>: Failed to establish a new connection: [Errno -2] Name or service not known'))
[33mservice_main            |[0m 2023-05-29T16:02:09.546194412Z 
[33mservice_main            |[0m 2023-05-29T16:02:09.546215240Z During handling of the above exception, another exception occurred:
[33mservice_main            |[0m 2023-05-29T16:02:09.546221213Z 
[33mservice_main            |[0m 2023-05-29T16:02:09.547043663Z Traceback (most recent call last):
[33mservice_main            |[0m 2023-05-29T16:02:09.548198660Z   File "/usr/lib/python3.10/logging/__init__.py", line 1100, in emit
[33mservice_main            |[0m 2023-05-29T16:02:09.548324101Z     msg = self.format(record)
[33mservice_main            |[0m 2023-05-29T16:02:09.549110088Z   File "/usr/lib/python3.10/logging/__init__.py", line 943, in format
[33mservice_main            |[0m 2023-05-29T16:02:09.549129295Z     return fmt.format(record)
[33mservice_main            |[0m 2023-05-29T16:02:09.549891147Z   File "/usr/lib/python3.10/logging/__init__.py", line 678, in format
[33mservice_main            |[0m 2023-05-29T16:02:09.549910460Z     record.message = record.getMessage()
[33mservice_main            |[0m 2023-05-29T16:02:09.550678515Z   File "/usr/lib/python3.10/logging/__init__.py", line 368, in getMessage
[33mservice_main            |[0m 2023-05-29T16:02:09.550702568Z     msg = msg % self.args
[33mservice_main            |[0m 2023-05-29T16:02:09.551545209Z TypeError: not all arguments converted during string formatting
[33mservice_main            |[0m 2023-05-29T16:02:09.552418893Z Call stack:
[33mservice_main            |[0m 2023-05-29T16:02:09.553879226Z   File "<string>", line 1, in <module>
[33mservice_main            |[0m 2023-05-29T16:02:09.554826853Z   File "/usr/lib/python3.10/multiprocessing/spawn.py", line 116, in spawn_main
[33mservice_main            |[0m 2023-05-29T16:02:09.554923867Z     exitcode = _main(fd, parent_sentinel)
[33mservice_main            |[0m 2023-05-29T16:02:09.555858782Z   File "/usr/lib/python3.10/multiprocessing/spawn.py", line 129, in _main
[33mservice_main            |[0m 2023-05-29T16:02:09.556020922Z     return self._bootstrap(parent_sentinel)
[33mservice_main            |[0m 2023-05-29T16:02:09.556784515Z   File "/usr/lib/python3.10/multiprocessing/process.py", line 314, in _bootstrap
[33mservice_main            |[0m 2023-05-29T16:02:09.556881780Z     self.run()
[33mservice_main            |[0m 2023-05-29T16:02:09.557876747Z   File "/usr/lib/python3.10/multiprocessing/process.py", line 108, in run
[33mservice_main            |[0m 2023-05-29T16:02:09.557915549Z     self._target(*self._args, **self._kwargs)
[33mservice_main            |[0m 2023-05-29T16:02:09.558551266Z   File "/usr/local/lib/python3.10/dist-packages/uvicorn/_subprocess.py", line 76, in subprocess_started
[33mservice_main            |[0m 2023-05-29T16:02:09.558583285Z     target(sockets=sockets)
[33mservice_main            |[0m 2023-05-29T16:02:09.559144943Z   File "/usr/local/lib/python3.10/dist-packages/uvicorn/server.py", line 60, in run
[33mservice_main            |[0m 2023-05-29T16:02:09.559280220Z     return asyncio.run(self.serve(sockets=sockets))
[33mservice_main            |[0m 2023-05-29T16:02:09.559678958Z   File "/usr/lib/python3.10/asyncio/runners.py", line 44, in run
[33mservice_main            |[0m 2023-05-29T16:02:09.559883810Z     return loop.run_until_complete(main)
[33mservice_main            |[0m 2023-05-29T16:02:09.560252707Z   File "/usr/lib/python3.10/asyncio/base_events.py", line 633, in run_until_complete
[33mservice_main            |[0m 2023-05-29T16:02:09.560268565Z     self.run_forever()
[33mservice_main            |[0m 2023-05-29T16:02:09.560774785Z   File "/usr/lib/python3.10/asyncio/base_events.py", line 600, in run_forever
[33mservice_main            |[0m 2023-05-29T16:02:09.560793028Z     self._run_once()
[33mservice_main            |[0m 2023-05-29T16:02:09.561445429Z   File "/usr/lib/python3.10/asyncio/base_events.py", line 1896, in _run_once
[33mservice_main            |[0m 2023-05-29T16:02:09.561673033Z     handle._run()
[33mservice_main            |[0m 2023-05-29T16:02:09.562935236Z   File "/usr/lib/python3.10/asyncio/events.py", line 80, in _run
[33mservice_main            |[0m 2023-05-29T16:02:09.563030352Z     self._context.run(self._callback, *self._args)
[33mservice_main            |[0m 2023-05-29T16:02:09.563470919Z   File "/usr/local/lib/python3.10/dist-packages/uvicorn/protocols/http/httptools_impl.py", line 419, in run_asgi
[33mservice_main            |[0m 2023-05-29T16:02:09.563490731Z     result = await app(  # type: ignore[func-returns-value]
[33mservice_main            |[0m 2023-05-29T16:02:09.564201097Z   File "/usr/local/lib/python3.10/dist-packages/uvicorn/middleware/proxy_headers.py", line 78, in __call__
[33mservice_main            |[0m 2023-05-29T16:02:09.564221519Z     return await self.app(scope, receive, send)
[33mservice_main            |[0m 2023-05-29T16:02:09.564662863Z   File "/usr/local/lib/python3.10/dist-packages/fastapi/applications.py", line 271, in __call__
[33mservice_main            |[0m 2023-05-29T16:02:09.564680903Z     await super().__call__(scope, receive, send)
[33mservice_main            |[0m 2023-05-29T16:02:09.565288508Z   File "/usr/local/lib/python3.10/dist-packages/starlette/applications.py", line 118, in __call__
[33mservice_main            |[0m 2023-05-29T16:02:09.565308220Z     await self.middleware_stack(scope, receive, send)
[33mservice_main            |[0m 2023-05-29T16:02:09.565879374Z   File "/usr/local/lib/python3.10/dist-packages/starlette/middleware/errors.py", line 162, in __call__
[33mservice_main            |[0m 2023-05-29T16:02:09.566064142Z     await self.app(scope, receive, _send)
[33mservice_main            |[0m 2023-05-29T16:02:09.566331005Z   File "/usr/local/lib/python3.10/dist-packages/starlette/middleware/exceptions.py", line 68, in __call__
[33mservice_main            |[0m 2023-05-29T16:02:09.566464637Z     await self.app(scope, receive, sender)
[33mservice_main            |[0m 2023-05-29T16:02:09.566880478Z   File "/usr/local/lib/python3.10/dist-packages/fastapi/middleware/asyncexitstack.py", line 18, in __call__
[33mservice_main            |[0m 2023-05-29T16:02:09.566894264Z     await self.app(scope, receive, send)
[33mservice_main            |[0m 2023-05-29T16:02:09.567575634Z   File "/usr/local/lib/python3.10/dist-packages/starlette/routing.py", line 706, in __call__
[33mservice_main            |[0m 2023-05-29T16:02:09.567621859Z     await route.handle(scope, receive, send)
[33mservice_main            |[0m 2023-05-29T16:02:09.568225772Z   File "/usr/local/lib/python3.10/dist-packages/starlette/routing.py", line 276, in handle
[33mservice_main            |[0m 2023-05-29T16:02:09.568245756Z     await self.app(scope, receive, send)
[33mservice_main            |[0m 2023-05-29T16:02:09.569066509Z   File "/usr/local/lib/python3.10/dist-packages/starlette/routing.py", line 66, in app
[33mservice_main            |[0m 2023-05-29T16:02:09.569334071Z     response = await func(request)
[33mservice_main            |[0m 2023-05-29T16:02:09.569529750Z   File "/usr/local/lib/python3.10/dist-packages/fastapi/routing.py", line 237, in app
[33mservice_main            |[0m 2023-05-29T16:02:09.569544893Z     raw_response = await run_endpoint_function(
[33mservice_main            |[0m 2023-05-29T16:02:09.571607073Z Timeout elapsed, retrying...
[33mservice_main            |[0m 2023-05-29T16:02:09.573179544Z Failed attempt count: 6
[33mservice_main            |[0m 2023-05-29T16:02:09.573206943Z INFO:     172.18.0.1:60042 - "GET /presentationsAndAuthor/First%20Presentation HTTP/1.1" 500 Internal Server Error
[33mservice_main            |[0m 2023-05-29T16:02:09.572096383Z   File "/usr/local/lib/python3.10/dist-packages/fastapi/routing.py", line 163, in run_endpoint_function
[33mservice_main            |[0m 2023-05-29T16:02:09.573226655Z     return await dependant.call(**values)
[33mservice_main            |[0m 2023-05-29T16:02:09.573924401Z   File "/./service_main.py", line 110, in read_presentation
[33mservice_main            |[0m 2023-05-29T16:02:09.574077717Z     author = get_author(presentation.author_id)
[33mservice_main            |[0m 2023-05-29T16:02:09.574089557Z   File "/./cbhomemade.py", line 39, in wrapper
[33mservice_main            |[0m 2023-05-29T16:02:09.574217491Z     result = self.func(*args, **kwargs)
[33mservice_main            |[0m 2023-05-29T16:02:09.574226271Z   File "/./service_main.py", line 80, in get_author
[33mservice_main            |[0m 2023-05-29T16:02:09.574231887Z     logging.warning(">>> Error Connecting:", errc)
[33mservice_main            |[0m 2023-05-29T16:02:09.574237501Z Message: '>>> Error Connecting:'
[33mservice_main            |[0m 2023-05-29T16:02:09.574242865Z Arguments: (ConnectionError(MaxRetryError("HTTPConnectionPool(host='service_author', port=8081): Max retries exceeded with url: /authors/1 (Caused by NewConnectionError('<urllib3.connection.HTTPConnection object at 0x7f6c59a7d570>: Failed to establish a new connection: [Errno -2] Name or service not known'))")),)
[33mservice_main            |[0m 2023-05-29T16:02:10.281403369Z WARNING:root:Circuit "test-08" is "Status.OPEN", failures: 6
[33mservice_main            |[0m 2023-05-29T16:02:10.302565634Z WARNING:root:
[33mservice_main            |[0m 2023-05-29T16:02:10.895346151Z CRITICAL:root:Circuit OPEN
[33mservice_main            |[0m 2023-05-29T16:02:10.895812128Z INFO:     172.18.0.1:60048 - "GET /presentationsAndAuthor/First%20Presentation HTTP/1.1" 200 OK
[33mservice_main            |[0m 2023-05-29T16:02:11.306384255Z WARNING:root:Circuit "test-08" is "Status.OPEN", failures: 6
[33mservice_main            |[0m 2023-05-29T16:02:11.319474164Z WARNING:root:
[33mservice_main            |[0m 2023-05-29T16:02:12.325258245Z WARNING:root:Circuit "test-08" is "Status.OPEN", failures: 6
[33mservice_main            |[0m 2023-05-29T16:02:12.351044423Z WARNING:root:
[33mservice_main            |[0m 2023-05-29T16:02:13.354933198Z WARNING:root:Circuit "test-08" is "Status.OPEN", failures: 6
[33mservice_main            |[0m 2023-05-29T16:02:13.376236825Z WARNING:root:
[33mservice_main            |[0m 2023-05-29T16:02:14.383286462Z WARNING:root:Circuit "test-08" is "Status.OPEN", failures: 6
[33mservice_main            |[0m 2023-05-29T16:02:14.412381557Z WARNING:root:
[33mservice_main            |[0m 2023-05-29T16:02:15.440512683Z WARNING:root:Circuit "test-08" is "Status.OPEN", failures: 6
[33mservice_main            |[0m 2023-05-29T16:02:15.481545957Z WARNING:root:
[33mservice_main            |[0m 2023-05-29T16:02:16.485702699Z WARNING:root:Circuit "test-08" is "Status.OPEN", failures: 6
[33mservice_main            |[0m 2023-05-29T16:02:16.528557268Z WARNING:root:
[33mservice_main            |[0m 2023-05-29T16:02:16.645020481Z CRITICAL:root:Circuit OPEN
[33mservice_main            |[0m 2023-05-29T16:02:16.651811103Z INFO:     172.18.0.1:60054 - "GET /presentationsAndAuthor/First%20Presentation HTTP/1.1" 200 OK
[33mservice_main            |[0m 2023-05-29T16:02:17.532252332Z WARNING:root:Circuit "test-08" is "Status.OPEN", failures: 6
[33mservice_main            |[0m 2023-05-29T16:02:17.564995983Z WARNING:root:
[33mservice_main            |[0m 2023-05-29T16:02:18.572212415Z WARNING:root:Circuit "test-08" is "Status.OPEN", failures: 6
[33mservice_main            |[0m 2023-05-29T16:02:18.598911172Z WARNING:root:
[33mservice_main            |[0m 2023-05-29T16:02:19.612013602Z WARNING:root:Circuit "test-08" is "Status.HALF_OPEN", failures: 6
[33mservice_main            |[0m 2023-05-29T16:02:19.643899019Z WARNING:root:
[33mservice_main            |[0m 2023-05-29T16:02:20.055601417Z Timeout elapsed, retrying...
[33mservice_main            |[0m 2023-05-29T16:02:20.055633564Z Moore
[33mservice_main            |[0m 2023-05-29T16:02:20.055638546Z Ok. Going back to CLOSED
[33mservice_main            |[0m 2023-05-29T16:02:20.055644188Z INFO:     172.18.0.1:60060 - "GET /presentationsAndAuthor/First%20Presentation HTTP/1.1" 200 OK
[33mservice_main            |[0m 2023-05-29T16:02:20.651202649Z WARNING:root:Circuit "test-08" is "Status.CLOSED", failures: 0
[33mservice_main            |[0m 2023-05-29T16:02:20.676786191Z WARNING:root:
[33mservice_main            |[0m 2023-05-29T16:02:21.681412763Z WARNING:root:Circuit "test-08" is "Status.CLOSED", failures: 0
[33mservice_main            |[0m 2023-05-29T16:02:21.710882193Z WARNING:root:
[33mservice_main            |[0m 2023-05-29T16:02:22.714137506Z WARNING:root:Circuit "test-08" is "Status.CLOSED", failures: 0
[33mservice_main            |[0m 2023-05-29T16:02:22.728102776Z WARNING:root:
[33mservice_main            |[0m 2023-05-29T16:02:23.735420890Z WARNING:root:Circuit "test-08" is "Status.CLOSED", failures: 0
[33mservice_main            |[0m 2023-05-29T16:02:23.778016907Z WARNING:root:
[33mservice_main            |[0m 2023-05-29T16:02:24.781878047Z WARNING:root:Circuit "test-08" is "Status.CLOSED", failures: 0
[33mservice_main            |[0m 2023-05-29T16:02:24.799624487Z WARNING:root:
[33mservice_main            |[0m 2023-05-29T16:02:25.802907697Z WARNING:root:Circuit "test-08" is "Status.CLOSED", failures: 0
[33mservice_main            |[0m 2023-05-29T16:02:25.830434869Z WARNING:root:
[33mservice_main            |[0m 2023-05-29T16:02:26.265834281Z Moore
[33mservice_main            |[0m 2023-05-29T16:02:26.265863476Z INFO:     172.18.0.1:60068 - "GET /presentationsAndAuthor/First%20Presentation HTTP/1.1" 200 OK
[33mservice_main            |[0m 2023-05-29T16:02:26.839014072Z WARNING:root:Circuit "test-08" is "Status.CLOSED", failures: 0
[33mservice_main            |[0m 2023-05-29T16:02:26.873014879Z WARNING:root:
[33mservice_main            |[0m 2023-05-29T16:02:27.886778428Z WARNING:root:Circuit "test-08" is "Status.CLOSED", failures: 0
[33mservice_main            |[0m 2023-05-29T16:02:27.917569825Z WARNING:root:
[33mservice_main            |[0m 2023-05-29T16:02:28.063320491Z Moore
[33mservice_main            |[0m 2023-05-29T16:02:28.063453227Z INFO:     172.18.0.1:60076 - "GET /presentationsAndAuthor/First%20Presentation HTTP/1.1" 200 OK
[33mservice_main            |[0m 2023-05-29T16:02:28.925880186Z WARNING:root:Circuit "test-08" is "Status.CLOSED", failures: 0
[33mservice_main            |[0m 2023-05-29T16:02:28.945919136Z WARNING:root:
[33mservice_main            |[0m 2023-05-29T16:02:29.950865481Z WARNING:root:Circuit "test-08" is "Status.CLOSED", failures: 0
[33mservice_main            |[0m 2023-05-29T16:02:29.956694844Z WARNING:root:
[33mservice_main            |[0m 2023-05-29T16:02:30.970497607Z WARNING:root:Circuit "test-08" is "Status.CLOSED", failures: 0
[33mservice_main            |[0m 2023-05-29T16:02:31.096740605Z WARNING:root:
[33mservice_main            |[0m 2023-05-29T16:02:32.106297179Z WARNING:root:Circuit "test-08" is "Status.CLOSED", failures: 0
[33mservice_main            |[0m 2023-05-29T16:02:32.172093591Z WARNING:root:
[33mservice_main            |[0m 2023-05-29T16:02:33.175932971Z WARNING:root:Circuit "test-08" is "Status.CLOSED", failures: 0
[33mservice_main            |[0m 2023-05-29T16:02:33.214174013Z WARNING:root:
[33mservice_main            |[0m 2023-05-29T16:02:34.218317204Z WARNING:root:Circuit "test-08" is "Status.CLOSED", failures: 0
[33mservice_main            |[0m 2023-05-29T16:02:34.265690184Z WARNING:root:
[33mservice_main            |[0m 2023-05-29T16:02:35.268742144Z WARNING:root:Circuit "test-08" is "Status.CLOSED", failures: 0
[33mservice_main            |[0m 2023-05-29T16:02:35.295559027Z WARNING:root:
[33mservice_main            |[0m 2023-05-29T16:02:36.298724558Z WARNING:root:Circuit "test-08" is "Status.CLOSED", failures: 0
[33mservice_main            |[0m 2023-05-29T16:02:36.319283370Z WARNING:root:
